Workbook

Sheet Read Me
B2: CASE STUDY 09
B3: Net Promoter Score Analysis
B4: David Izzulhaq, Data Analyst | davidizzulhaq.github.io
B6: Business question
B7: Customers rate us, but one average score hides where we delight and where we frustrate. Which touchpoints lift loyalty and which drag it down, and is sentiment improving?
B9: Dataset
B10: 1,150 survey responses (score 0 to 10) across 5 touchpoints over 10 months. The raw export had touchpoint noise, mixed dates and blanks.
B12: Method
B13: 1) Clean and standardise. 2) Classify each response as Promoter (9 to 10), Passive (7 to 8) or Detractor (0 to 6). 3) Compute NPS (percent promoters minus percent detractors) overall, per touchpoint and per month.
B15: Headline results
B16: NPS varies sharply by touchpoint; the weakest touchpoint is the clearest place to improve. The monthly trend shows whether changes are working.
B18: How to read this file
... B22: Every formula is open. No black boxes.

Sheet Raw Data
A1: RAW DATA (as received, before cleaning)
A2: 1,162 rows. Real-world mess: mixed formats, text-numbers, duplicates, blanks, inconsistent casing.
A4: responden | B4: bulan | C4: touchpoint | D4: skor | E4: kategori
A5: R5910 | B5: 2025-11-01 | C5: Produk | D5: 8 | E5: Passive
A6: R6054 | B6: 2026-02-01 | C6: Layanan | D6: 9 | E6: Promoter
A7: R5986 | B7: 2026-03-01 | C7: Produk | D7: 8 | E7: Passive
A8: R5388 | B8: 01/09/2025 | C8: Harga | D8: 10 | E8: Promoter
A9: R5421 | B9: 2025-09-01 | C9: Produk | D9: 8 | E9: Passive
A10: R5670 | B10: 2026-04-01 | C10: Harga | D10: 6 | E10: Detractor
A11: R5173 | B11: 2025-11-01 | C11: Produk | D11: 10 | E11: Promoter
A12: R5567 | B12: 2026-03-01 | C12: Produk | D12: 10 | E12: Promoter
A13: R5121 | B13: 01/05/2026 | C13: Pengiriman | D13: 8 | E13: Passive
A14: R6110 | B14: 2026-05-01 | C14: Aplikasi | D14: 6 | E14: Detractor
A15: R5145 | B15: Apr 2026 | C15: PENGIRIMAN | D15: 8 | E15: Passive
A16: R5738 | B16: 2025-10-01 | C16: Layanan | D16: 9 | E16: Promoter
... A22: R5871 | B22: 2025-09-01 | C22: APLIKASI | D22: 7 | E22: Passive
A23: R5278 | B23: 2025-10-01 | C23: Produk | E23: Promoter
A24: R5397 | B24: 01/11/2025 | C24: Aplikasi | D24: 6 | E24: Detractor
A25: R5263 | B25: 2026-05-01 | C25: Produk | D25: 7 | E25: Passive
A26: R5536 | B26: 2026-04-01 | C26: Produk | D26: 9 | E26: promoter
A27: R5733 | B27: 2026-04-01 | C27: Harga | D27: 9 | E27: Promoter
A28: R5783 | B28: 2025-09-01 | C28: Layanan | D28: 6 | E28: Detractor
A29: R5677 | B29: May 2026 | C29: Harga | D29: 10 | E29: promoter
A30: R6037 | B30: Mar 2026 | C30: Aplikasi | D30: 9 | E30: Promoter
A31: R6084 | B31: Nov 2025 | C31: APLIKASI | D31: 9 | E31: Promoter
A32: R5956 | B32: 2026-06-01 | C32: Produk | D32: 10 | E32: Promoter
A33: R5618 | B33: 2026-02-01 | C33: Produk | D33: 10 | E33: Promoter
A34: R5927 | B34: 01/09/2025 | C34: Produk | D34: 10 | E34: Promoter
A35: R6136 | B35: 2026-01-01 | C35: Produk | D35: 10 | E35: Promoter
... A84: R5377 | B84: 2026-02-01 | C84: layanan | D84: 8 | E84: Passive
A85: R5444 | B85: 2026-03-01 | C85: pengiriman | E85: Passive
A86: R5528 | B86: 2025-10-01 | C86: PENGIRIMAN | D86: 10 | E86: Promoter
A87: R5883 | B87: 2026-02-01 | C87: PRODUK | D87: 6 | E87: Detractor
A88: R5157 | B88: 2025-11-01 | C88: Layanan | E88: Promoter
A89: R5204 | B89: 01/09/2025 | C89: Harga | D89: 10 | E89: Promoter
A90: R5418 | B90: 2025-11-01 | C90: Pengiriman | D90: 5 | E90: Detractor
A91: R5712 | B91: 2026-06-01 | C91: harga | D91: 8 | E91: Passive
A92: R5558 | B92: 2026-02-01 | C92: Produk | D92: 10 | E92: Promoter
A93: R5866 | B93: Jun 2026 | C93: Aplikasi | D93: 10 | E93: Promoter
A94: R5922 | B94: 2026-02-01 | C94: APLIKASI | D94: 10 | E94: Promoter
...

Sheet Cleaning
A1: CLEANING LOG
A2: Every issue found, the fix applied, and how many rows it touched.
A4: Issue found | B4: Example | C4: Fix applied | D4: Rows affected
A5: Touchpoint: case and spacing | B5: 'layanan', 'PRODUK' | C5: TRIM + PROPER normalisation | D5: 345
A6: Inconsistent date formats | B6: 01/09/2025 and Sep 2025 | C6: Parsed to real Excel dates, then YYYY-MM | D6: 276
A7: Missing scores | B7: (blank cell) | C7: Excluded from NPS until recovered | D7: 34
A8: Category casing | B8: 'promoter', 'detractor' | C8: PROPER case normalisation | D8: 115
A9: Duplicate response rows | B9: same respondent twice | C9: Removed exact duplicates | D9: 12
A10: Rows in, then after de-duplication | D10: 1,162 -> 1,150
A13: LIVE FORMULA DEMO (column C recomputes from column A)
A15: Raw value | B15: Formula (shown as text) | C15: Result (live)
A16: layanan | B16: PROPER(TRIM(A16)) | C16: =PROPER(TRIM(A16))
A17: Sep 2025 | B17: TEXT(DATEVALUE(A17),"YYYY-MM") | C17: =TEXT(DATEVALUE(A17),"YYYY-MM")
A18: promoter | B18: PROPER(A18) | C18: =PROPER(A18)

Sheet Clean Data
A1: responden | B1: bulan | C1: touchpoint | D1: skor | E1: kategori | F1: month
A2: R5000 | B2: 46113 | C2: Produk | D2: 7 | E2: Passive | F2: =TEXT($B2,"YYYY-MM")
A3: R5001 | B3: 45901 | C3: Harga | D3: 8 | E3: Passive | F3: =TEXT($B3,"YYYY-MM")
A4: R5002 | B4: 45962 | C4: Produk | D4: 8 | E4: Passive | F4: =TEXT($B4,"YYYY-MM")
A5: R5003 | B5: 46082 | C5: Aplikasi | D5: 8 | E5: Passive | F5: =TEXT($B5,"YYYY-MM")
A6: R5004 | B6: 46054 | C6: Aplikasi | D6: 9 | E6: Promoter | F6: =TEXT($B6,"YYYY-MM")
A7: R5005 | B7: 46023 | C7: Aplikasi | D7: 7 | E7: Passive | F7: =TEXT($B7,"YYYY-MM")
A8: R5006 | B8: 46082 | C8: Produk | D8: 8 | E8: Passive | F8: =TEXT($B8,"YYYY-MM")
A9: R5007 | B9: 46113 | C9: Produk | D9: 10 | E9: Promoter | F9: =TEXT($B9,"YYYY-MM")
A10: R5008 | B10: 46082 | C10: Harga | D10: 7 | E10: Passive | F10: =TEXT($B10,"YYYY-MM")
A11: R5009 | B11: 45901 | C11: Layanan | D11: 10 | E11: Promoter | F11: =TEXT($B11,"YYYY-MM")
A12: R5010 | B12: 46174 | C12: Produk | D12: 8 | E12: Passive | F12: =TEXT($B12,"YYYY-MM")
A13: R5011 | B13: 46023 | C13: Produk | D13: 6 | E13: Detractor | F13: =TEXT($B13,"YYYY-MM")
... A1151: R6149 | B1151: 46023 | C1151: Pengiriman | D1151: 4 | E1151: Detractor | F1151: =TEXT($B1151,"YYYY-MM")

Sheet Analysis
A1: ANALYSIS (live NPS = %promoters - %detractors, from score, referencing Clean Data)
A3: Key metrics | H3: Monthly NPS trend
A4: Responses | B4: =COUNTA('Clean Data'!$A$2:$A$1151) | H4: Month | I4: Responses | J4: NPS
A5: Overall NPS | B5: =ROUND((COUNTIF('Clean Data'!$D$2:$D$1151,">=9")-COUNTIF('Clean Data'!$D$2:$D$1151,"<=6"))/COUNTA('Clean Data'!$D$2:$D$1151)*100,0) | H5: 2025-09 | I5: =COUNTIF('Clean Data'!$F$2:$F$1151,$H5) | J5: =ROUND((COUNTIFS('Clean Data'!$F$2:$F$1151,$H5,'Clean Data'!$D$2:$D$1151,">=9")-COUNTIFS('Clean Data'!$F$2:$F$1151,$H5,'Clean Data'!$D$2:$D$1151,"<=6"))/COUNTIF('Clean Data'!$F$2:$F$1151,$H5)*100,0)
A6: Promoters | B6: =COUNTIF('Clean Data'!$D$2:$D$1151,">=9")/COUNTA('Clean Data'!$D$2:$D$1151) | H6: 2025-10 | I6: =COUNTIF('Clean Data'!$F$2:$F$1151,$H6) | J6: =ROUND((COUNTIFS('Clean Data'!$F$2:$F$1151,$H6,'Clean Data'!$D$2:$D$1151,">=9")-COUNTIFS('Clean Data'!$F$2:$F$1151,$H6,'Clean Data'!$D$2:$D$1151,"<=6"))/COUNTIF('Clean Data'!$F$2:$F$1151,$H6)*100,0)
A7: Best touchpoint | B7: =INDEX(A14:A18,MATCH(MAX(E14:E18),E14:E18,0)) | H7: 2025-11 | I7: =COUNTIF('Clean Data'!$F$2:$F$1151,$H7) | J7: =ROUND((COUNTIFS('Clean Data'!$F$2:$F$1151,$H7,'Clean Data'!$D$2:$D$1151,">=9")-COUNTIFS('Clean Data'!$F$2:$F$1151,$H7,'Clean Data'!$D$2:$D$1151,"<=6"))/COUNTIF('Clean Data'!$F$2:$F$1151,$H7)*100,0)
A8: Weakest touchpoint | B8: =INDEX(A14:A18,MATCH(MIN(E14:E18),E14:E18,0)) | H8: 2025-12 | I8: =COUNTIF('Clean Data'!$F$2:$F$1151,$H8) | J8: =ROUND((COUNTIFS('Clean Data'!$F$2:$F$1151,$H8,'Clean Data'!$D$2:$D$1151,">=9")-COUNTIFS('Clean Data'!$F$2:$F$1151,$H8,'Clean Data'!$D$2:$D$1151,"<=6"))/COUNTIF('Clean Data'!$F$2:$F$1151,$H8)*100,0)
H9: 2026-01 | I9: =COUNTIF('Clean Data'!$F$2:$F$1151,$H9) | J9: =ROUND((COUNTIFS('Clean Data'!$F$2:$F$1151,$H9,'Clean Data'!$D$2:$D$1151,">=9")-COUNTIFS('Clean Data'!$F$2:$F$1151,$H9,'Clean Data'!$D$2:$D$1151,"<=6"))/COUNTIF('Clean Data'!$F$2:$F$1151,$H9)*100,0)
H10: 2026-02 | I10: =COUNTIF('Clean Data'!$F$2:$F$1151,$H10) | J10: =ROUND((COUNTIFS('Clean Data'!$F$2:$F$1151,$H10,'Clean Data'!$D$2:$D$1151,">=9")-COUNTIFS('Clean Data'!$F$2:$F$1151,$H10,'Clean Data'!$D$2:$D$1151,"<=6"))/COUNTIF('Clean Data'!$F$2:$F$1151,$H10)*100,0)
H11: 2026-03 | I11: =COUNTIF('Clean Data'!$F$2:$F$1151,$H11) | J11: =ROUND((COUNTIFS('Clean Data'!$F$2:$F$1151,$H11,'Clean Data'!$D$2:$D$1151,">=9")-COUNTIFS('Clean Data'!$F$2:$F$1151,$H11,'Clean Data'!$D$2:$D$1151,"<=6"))/COUNTIF('Clean Data'!$F$2:$F$1151,$H11)*100,0)
A12: NPS by touchpoint | H12: 2026-04 | I12: =COUNTIF('Clean Data'!$F$2:$F$1151,$H12) | J12: =ROUND((COUNTIFS('Clean Data'!$F$2:$F$1151,$H12,'Clean Data'!$D$2:$D$1151,">=9")-COUNTIFS('Clean Data'!$F$2:$F$1151,$H12,'Clean Data'!$D$2:$D$1151,"<=6"))/COUNTIF('Clean Data'!$F$2:$F$1151,$H12)*100,0)
A13: Touchpoint | B13: Responses | C13: Promoters | D13: Detractors | E13: NPS | H13: 2026-05 | I13: =COUNTIF('Clean Data'!$F$2:$F$1151,$H13) | J13: =ROUND((COUNTIFS('Clean Data'!$F$2:$F$1151,$H13,'Clean Data'!$D$2:$D$1151,">=9")-COUNTIFS('Clean Data'!$F$2:$F$1151,$H13,'Clean Data'!$D$2:$D$1151,"<=6"))/COUNTIF('Clean Data'!$F$2:$F$1151,$H13)*100,0)
A14: Aplikasi | B14: =COUNTIF('Clean Data'!$C$2:$C$1151,$A14) | C14: =COUNTIFS('Clean Data'!$C$2:$C$1151,$A14,'Clean Data'!$D$2:$D$1151,">=9") | D14: =COUNTIFS('Clean Data'!$C$2:$C$1151,$A14,'Clean Data'!$D$2:$D$1151,"<=6") | E14: =ROUND((C14-D14)/B14*100,0) | H14: 2026-06 | I14: =COUNTIF('Clean Data'!$F$2:$F$1151,$H14) | J14: =ROUND((COUNTIFS('Clean Data'!$F$2:$F$1151,$H14,'Clean Data'!$D$2:$D$1151,">=9")-COUNTIFS('Clean Data'!$F$2:$F$1151,$H14,'Clean Data'!$D$2:$D$1151,"<=6"))/COUNTIF('Clean Data'!$F$2:$F$1151,$H14)*100,0)
A15: Harga | B15: =COUNTIF('Clean Data'!$C$2:$C$1151,$A15) | C15: =COUNTIFS('Clean Data'!$C$2:$C$1151,$A15,'Clean Data'!$D$2:$D$1151,">=9") | D15: =COUNTIFS('Clean Data'!$C$2:$C$1151,$A15,'Clean Data'!$D$2:$D$1151,"<=6") | E15: =ROUND((C15-D15)/B15*100,0)
A16: Layanan | B16: =COUNTIF('Clean Data'!$C$2:$C$1151,$A16) | C16: =COUNTIFS('Clean Data'!$C$2:$C$1151,$A16,'Clean Data'!$D$2:$D$1151,">=9") | D16: =COUNTIFS('Clean Data'!$C$2:$C$1151,$A16,'Clean Data'!$D$2:$D$1151,"<=6") | E16: =ROUND((C16-D16)/B16*100,0)
A17: Pengiriman | B17: =COUNTIF('Clean Data'!$C$2:$C$1151,$A17) | C17: =COUNTIFS('Clean Data'!$C$2:$C$1151,$A17,'Clean Data'!$D$2:$D$1151,">=9") | D17: =COUNTIFS('Clean Data'!$C$2:$C$1151,$A17,'Clean Data'!$D$2:$D$1151,"<=6") | E17: =ROUND((C17-D17)/B17*100,0)
A18: Produk | B18: =COUNTIF('Clean Data'!$C$2:$C$1151,$A18) | C18: =COUNTIFS('Clean Data'!$C$2:$C$1151,$A18,'Clean Data'!$D$2:$D$1151,">=9") | D18: =COUNTIFS('Clean Data'!$C$2:$C$1151,$A18,'Clean Data'!$D$2:$D$1151,"<=6") | E18: =ROUND((C18-D18)/B18*100,0)
A21: Response mix
A22: Category | B22: Count | C22: Share
A23: Promoters (9-10) | B23: =COUNTIF('Clean Data'!$D$2:$D$1151,">=9") | C23: =B23/SUM($B$23:$B$25)
A24: Passives (7-8) | B24: =COUNTA('Clean Data'!$D$2:$D$1151)-COUNTIF('Clean Data'!$D$2:$D$1151,">=9")-COUNTIF('Clean Data'!$D$2:$D$1151,"<=6") | C24: =B24/SUM($B$23:$B$25)
A25: Detractors (0-6) | B25: =COUNTIF('Clean Data'!$D$2:$D$1151,"<=6") | C25: =B25/SUM($B$23:$B$25)

Sheet Dashboard
A1: DASHBOARD
A2: Net Promoter Score Analysis. Charts read live from Analysis. Same view as the web case study.
A4: Responses | C4: Overall NPS | E4: Promoters | G4: Best | I4: Weakest | K4: Touchpoints
A5: =Analysis!B4 | C5: =Analysis!B5 | E5: =Analysis!B6 | G5: =Analysis!B7 | I5: =Analysis!B8 | K5: =5
A24: The lowest-NPS touchpoint is the clearest fix. A weak one drags the whole score down. | I24: NPS counts promoters minus detractors. Passives do not count but are upgrade targets.
A44: Track NPS monthly to see whether fixes are working. A rising line means loyalty is improving.
A47: Recommendations
A48: - Fix the weakest touchpoint first; it pulls the overall score down the most.
A49: - Convert Passives to Promoters with small experience improvements; they are close.
A50: - Follow up with Detractors directly to recover them and learn the root causes.
A51: - Watch the monthly trend after each change to confirm it actually lifts NPS.

Sheet VBA
A1: VBA AUTOMATION (also provided as Module1.bas next to this file)
A2: Paste into the VBA editor (Alt+F11, Insert, Module) to normalise a fresh raw paste.
A4: Attribute VB_Name = "Module1"
A5: ' One-click cleaner for the "Raw Data" sheet: touchpoint and category casing.
A6: Sub CleanRawData()
A7: Dim ws As Worksheet, lastRow As Long, r As Long
A8: Set ws = ThisWorkbook.Sheets("Raw Data")
A9: lastRow = ws.Cells(ws.Rows.Count, 1).End(xlUp).Row
A10: Application.ScreenUpdating = False
A11: For r = 5 To lastRow
A12: ws.Cells(r, 3).Value = Application.WorksheetFunction.Proper(Trim(ws.Cells(r, 3).Value)) ' touchpoint
A13: ws.Cells(r, 5).Value = Application.WorksheetFunction.Proper(Trim(ws.Cells(r, 5).Value)) ' kategori
... A17: End Sub
