Workbook

Sheet Read Me
B2: CASE STUDY 08
B3: Customer Segmentation
B4: David Izzulhaq, Data Analyst | davidizzulhaq.github.io
B6: Business question
B7: We treat every customer the same. Who are our most valuable customers, who is slipping away, and how should each group be handled differently?
B9: Dataset
B10: 1,100 customers with total spend, order count, tenure and recency. The raw export had text-numbers, unit text and blanks.
B12: Method
B13: 1) Clean and standardise. 2) Segment customers on value (spend) and engagement (recency) into four groups. 3) Profile each segment by spend, orders, tenure and recency. 4) Size each segment and its revenue contribution.
B15: Headline results
B16: Four clear segments emerge: VIPs to protect, Loyal to nurture, At risk to win back, and Dormant to re-activate or let go. A small VIP group drives outsized revenue.
B18: How to read this file
... B22: Every formula is open. No black boxes.

Sheet Raw Data
A1: RAW DATA (as received, before cleaning)
A2: 1,113 rows. Real-world mess: mixed formats, text-numbers, duplicates, blanks, inconsistent casing.
A4: customer_id | B4: total_spend | C4: n_orders | D4: tenure_days | E4: recency_days
A5: C3210 | B5: 1674741 | C5: 6 | D5: 13 | E5: 21
A6: C3650 | B6: 10180376 | C6: 31 | D6: 637 | E6: 17 days
A7: C4056 | B7: 2768582 | C7: 21 | D7: 566 | E7: 24
A8: C3190 | B8: 529049 | C8: 9 | D8: 165 | E8: 124
A9: C3203 | B9: 4904993 | C9: 8 | D9: 294 | E9: 33
A10: C3810 | B10: 2663792 | C10: 11 | D10: 433 | E10: 21
A11: C3444 | B11: 3546833 | C11: 16 | D11: 272 | E11: 40
A12: C3325 | B12: 1612195 | C12: 1 | D12: 25 | E12: 1 days
A13: C4099 | B13: 995711 | C13: 4 | D13: 487 | E13: 91
A14: C3937 | B14: 387345 | C14: 1 | D14: 61 | E14: 30
A15: C3777 | B15: Rp 445.491 | C15: 2 | D15: 539 | E15: 40
A16: C3461 | B16: 1172926 | C16: 5 | D16: 111 | E16: 91
A17: C3834 | B17: 1116501 | C17: 6 | D17: 338 | E17: 127
A18: C3583 | B18: 2598561 | C18: 5 | D18: 460 | E18: 31
A19: C3227 | B19: 1486516 | D19: 48 | E19: 55
A20: C4086 | B20: 941505 | C20: 4 | D20: 69 | E20: 64
A21: C3048 | B21: 1398014 | C21: 4 | D21: 38 | E21: 4
A22: C3477 | B22: Rp 445.700 | C22: 3 | D22: 272 | E22: 43
A23: C3078 | B23: 1219310 | C23: 3 | D23: 153 | E23: 12
A24: C3888 | B24: 827865 | C24: 3 | D24: 307 | E24: 77
A25: C3848 | B25: 1018421 | C25: 4 | D25: 321 | E25: 55
A26: C3580 | B26: Rp 1.557.314 | C26: 5 | D26: 134 | E26: 29 days
A27: C3996 | B27: Rp 8.621.455 | C27: 30 | D27: 693 | E27: 14
A28: C3965 | B28: 1581562 | C28: 5 | D28: 58 | E28: 1
A29: C4034 | B29: 1333549 | C29: 1 | D29: 374 | E29: 56
A30: C3904 | B30: Rp 2.627.037 | C30: 15 | D30: 378 | E30: 16
A31: C3214 | B31: 666598 | C31: 4 | D31: 48 | E31: 76
A32: C3401 | B32: 1330075 | C32: 3 | D32: 302 | E32: 80 days
A33: C3381 | B33: 0 | C33: 1 | D33: 56 | E33: 20 days
A34: C3493 | B34: Rp 7.970.493 | C34: 27 | D34: 782 | E34: 26
A35: C3910 | B35: 260616 | C35: 8 | D35: 167 | E35: 97
A36: C3491 | B36: Rp 8.688.623 | C36: 28 | D36: 732 | E36: 1
A37: C3617 | B37: 3999344 | C37: 18 | D37: 407 | E37: 3
A38: C3765 | B38: Rp 2.628.955 | C38: 16 | D38: 414 | E38: 16
A39: C4028 | B39: 214148 | C39: 3 | D39: 100 | E39: 9
A40: C3840 | B40: Rp 913.850 | C40: 5 | D40: 212 | E40: 62
A41: C3426 | B41: Rp 3.220.721 | C41: 12 | D41: 556 | E41: 34 days
...

Sheet Cleaning
A1: CLEANING LOG
A2: Every issue found, the fix applied, and how many rows it touched.
A4: Issue found | B4: Example | C4: Fix applied | D4: Rows affected
A5: Total spend stored as text | B5: 'Rp 1.437.386' | C5: Strip 'Rp' and dots, convert with VALUE() | D5: 242
A6: Missing order count | B6: (blank cell) | C6: Recovered from order history | D6: 33
A7: Recency stored with unit text | B7: '30 days' | C7: Stripped ' days', kept the number | D7: 165
A8: Duplicate customer rows | B8: same customer_id twice | C8: Removed exact duplicates | D8: 13
A9: Rows in, then after de-duplication | D9: 1,113 -> 1,100
A12: LIVE FORMULA DEMO (column C recomputes from column A)
A14: Raw value | B14: Formula (shown as text) | C14: Result (live)
A15: Rp 1.437.386 | B15: VALUE(SUBSTITUTE(SUBSTITUTE(A15,"Rp ",""),".","")) | C15: =VALUE(SUBSTITUTE(SUBSTITUTE(A15,"Rp ",""),".",""))
A16: 30 days | B16: VALUE(SUBSTITUTE(A16," days","")) | C16: =VALUE(SUBSTITUTE(A16," days",""))

Sheet Clean Data
A1: customer_id | B1: total_spend | C1: n_orders | D1: tenure_days | E1: recency_days | F1: segment
A2: C3000 | B2: 3831395 | C2: 11 | D2: 549 | E2: 19 | F2: =IF($B2>=Analysis!$P$1,IF($E2<=Analysis!$P$2,"VIP","At risk"),IF($E2<=Analysis!$P$2,"Loyal","Dormant"))
A3: C3001 | B3: 1824860 | C3: 4 | D3: 33 | E3: 34 | F3: =IF($B3>=Analysis!$P$1,IF($E3<=Analysis!$P$2,"VIP","At risk"),IF($E3<=Analysis!$P$2,"Loyal","Dormant"))
A4: C3002 | B4: 1917246 | C4: 10 | D4: 369 | E4: 30 | F4: =IF($B4>=Analysis!$P$1,IF($E4<=Analysis!$P$2,"VIP","At risk"),IF($E4<=Analysis!$P$2,"Loyal","Dormant"))
A5: C3003 | B5: 3187446 | C5: 14 | D5: 231 | E5: 16 | F5: =IF($B5>=Analysis!$P$1,IF($E5<=Analysis!$P$2,"VIP","At risk"),IF($E5<=Analysis!$P$2,"Loyal","Dormant"))
A6: C3004 | B6: 10266357 | C6: 37 | D6: 701 | E6: 1 | F6: =IF($B6>=Analysis!$P$1,IF($E6<=Analysis!$P$2,"VIP","At risk"),IF($E6<=Analysis!$P$2,"Loyal","Dormant"))
A7: C3005 | B7: 3007561 | C7: 10 | D7: 441 | E7: 12 | F7: =IF($B7>=Analysis!$P$1,IF($E7<=Analysis!$P$2,"VIP","At risk"),IF($E7<=Analysis!$P$2,"Loyal","Dormant"))
A8: C3006 | B8: 1191792 | C8: 4 | D8: 295 | E8: 133 | F8: =IF($B8>=Analysis!$P$1,IF($E8<=Analysis!$P$2,"VIP","At risk"),IF($E8<=Analysis!$P$2,"Loyal","Dormant"))
A9: C3007 | B9: 690781 | C9: 3 | D9: 327 | E9: 80 | F9: =IF($B9>=Analysis!$P$1,IF($E9<=Analysis!$P$2,"VIP","At risk"),IF($E9<=Analysis!$P$2,"Loyal","Dormant"))
A10: C3008 | B10: 601518 | C10: 6 | D10: 236 | E10: 103 | F10: =IF($B10>=Analysis!$P$1,IF($E10<=Analysis!$P$2,"VIP","At risk"),IF($E10<=Analysis!$P$2,"Loyal","Dormant"))
A11: C3009 | B11: 6249343 | C11: 29 | D11: 468 | E11: 23 | F11: =IF($B11>=Analysis!$P$1,IF($E11<=Analysis!$P$2,"VIP","At risk"),IF($E11<=Analysis!$P$2,"Loyal","Dormant"))
A12: C3010 | B12: 1311990 | C12: 5 | D12: 263 | E12: 113 | F12: =IF($B12>=Analysis!$P$1,IF($E12<=Analysis!$P$2,"VIP","At risk"),IF($E12<=Analysis!$P$2,"Loyal","Dormant"))
A13: C3011 | B13: 850581 | C13: 2 | D13: 350 | E13: 53 | F13: =IF($B13>=Analysis!$P$1,IF($E13<=Analysis!$P$2,"VIP","At risk"),IF($E13<=Analysis!$P$2,"Loyal","Dormant"))
... A1101: C4099 | B1101: 995711 | C1101: 4 | D1101: 487 | E1101: 91 | F1101: =IF($B1101>=Analysis!$P$1,IF($E1101<=Analysis!$P$2,"VIP","At risk"),IF($E1101<=Analysis!$P$2,"Loyal","Dormant"))

Sheet Analysis
A1: ANALYSIS (live value x recency segmentation referencing Clean Data) | O1: Median spend | P1: =MEDIAN('Clean Data'!$B$2:$B$1101)
O2: Median recency | P2: =MEDIAN('Clean Data'!$E$2:$E$1101)
A3: Key metrics | O3: Rule | P3: spend vs median (value) x recency vs median (engagement)
A4: Customers | B4: =COUNTA('Clean Data'!$A$2:$A$1101)
A5: Total spend | B5: =SUM('Clean Data'!$B$2:$B$1101)
A6: VIP customers | B6: =COUNTIF('Clean Data'!$F$2:$F$1101,"VIP")
A7: VIP revenue share | B7: =SUMIF('Clean Data'!$F$2:$F$1101,"VIP",'Clean Data'!$B$2:$B$1101)/SUM('Clean Data'!$B$2:$B$1101)
A8: At-risk customers | B8: =COUNTIF('Clean Data'!$F$2:$F$1101,"At risk")
A12: Segment profile
A13: Segment | B13: Customers | C13: Total spend | D13: Avg spend | E13: Avg orders | F13: Avg recency (days) | G13: Avg tenure (days)
A14: VIP | B14: =COUNTIF('Clean Data'!$F$2:$F$1101,$A14) | C14: =SUMIF('Clean Data'!$F$2:$F$1101,$A14,'Clean Data'!$B$2:$B$1101) | D14: =IFERROR(AVERAGEIF('Clean Data'!$F$2:$F$1101,$A14,'Clean Data'!$B$2:$B$1101),0) | E14: =IFERROR(AVERAGEIF('Clean Data'!$F$2:$F$1101,$A14,'Clean Data'!$C$2:$C$1101),0) | F14: =IFERROR(AVERAGEIF('Clean Data'!$F$2:$F$1101,$A14,'Clean Data'!$E$2:$E$1101),0) | G14: =IFERROR(AVERAGEIF('Clean Data'!$F$2:$F$1101,$A14,'Clean Data'!$D$2:$D$1101),0)
A15: Loyal | B15: =COUNTIF('Clean Data'!$F$2:$F$1101,$A15) | C15: =SUMIF('Clean Data'!$F$2:$F$1101,$A15,'Clean Data'!$B$2:$B$1101) | D15: =IFERROR(AVERAGEIF('Clean Data'!$F$2:$F$1101,$A15,'Clean Data'!$B$2:$B$1101),0) | E15: =IFERROR(AVERAGEIF('Clean Data'!$F$2:$F$1101,$A15,'Clean Data'!$C$2:$C$1101),0) | F15: =IFERROR(AVERAGEIF('Clean Data'!$F$2:$F$1101,$A15,'Clean Data'!$E$2:$E$1101),0) | G15: =IFERROR(AVERAGEIF('Clean Data'!$F$2:$F$1101,$A15,'Clean Data'!$D$2:$D$1101),0)
A16: At risk | B16: =COUNTIF('Clean Data'!$F$2:$F$1101,$A16) | C16: =SUMIF('Clean Data'!$F$2:$F$1101,$A16,'Clean Data'!$B$2:$B$1101) | D16: =IFERROR(AVERAGEIF('Clean Data'!$F$2:$F$1101,$A16,'Clean Data'!$B$2:$B$1101),0) | E16: =IFERROR(AVERAGEIF('Clean Data'!$F$2:$F$1101,$A16,'Clean Data'!$C$2:$C$1101),0) | F16: =IFERROR(AVERAGEIF('Clean Data'!$F$2:$F$1101,$A16,'Clean Data'!$E$2:$E$1101),0) | G16: =IFERROR(AVERAGEIF('Clean Data'!$F$2:$F$1101,$A16,'Clean Data'!$D$2:$D$1101),0)
A17: Dormant | B17: =COUNTIF('Clean Data'!$F$2:$F$1101,$A17) | C17: =SUMIF('Clean Data'!$F$2:$F$1101,$A17,'Clean Data'!$B$2:$B$1101) | D17: =IFERROR(AVERAGEIF('Clean Data'!$F$2:$F$1101,$A17,'Clean Data'!$B$2:$B$1101),0) | E17: =IFERROR(AVERAGEIF('Clean Data'!$F$2:$F$1101,$A17,'Clean Data'!$C$2:$C$1101),0) | F17: =IFERROR(AVERAGEIF('Clean Data'!$F$2:$F$1101,$A17,'Clean Data'!$E$2:$E$1101),0) | G17: =IFERROR(AVERAGEIF('Clean Data'!$F$2:$F$1101,$A17,'Clean Data'!$D$2:$D$1101),0)

Sheet Dashboard
A1: DASHBOARD
A2: Customer Segmentation. Charts read live from Analysis. Same view as the web case study.
A4: Customers | C4: Total spend | E4: VIP customers | G4: VIP rev share | I4: At-risk | K4: Segments
A5: =Analysis!B4 | C5: =Analysis!B5 | E5: =Analysis!B6 | G5: =Analysis!B7 | I5: =Analysis!B8 | K5: =4
A24: How many customers fall in each group. VIPs are few but valuable. | I24: A small VIP group drives an outsized share of revenue. Protect it first.
A43: Average value per customer. Use it to size win-back offers for At risk and Dormant.
A46: Recommendations
A47: - Give VIPs priority service and early access; losing one hurts most.
A48: - Nurture Loyal customers with relevant offers to grow them into VIPs.
A49: - Win back At risk customers now with a targeted offer before they go Dormant.
A50: - Re-activate Dormant customers cheaply or stop spending on them.

Sheet VBA
A1: VBA AUTOMATION (also provided as Module1.bas next to this file)
A2: Paste into the VBA editor (Alt+F11, Insert, Module) to normalise a fresh raw paste.
A4: Attribute VB_Name = "Module1"
A5: ' One-click cleaner for the "Raw Data" sheet: "Rp" spend text and "x days" recency text to numbers.
A6: Sub CleanRawData()
A7: Dim ws As Worksheet, lastRow As Long, r As Long, v As String
A8: Set ws = ThisWorkbook.Sheets("Raw Data")
A9: lastRow = ws.Cells(ws.Rows.Count, 1).End(xlUp).Row
A10: Application.ScreenUpdating = False
A11: For r = 5 To lastRow
A12: v = CStr(ws.Cells(r, 2).Value)
A13: If InStr(1, v, "Rp", vbTextCompare) > 0 Then
... A25: End Sub
