Workbook

Sheet Read Me
B2: CASE STUDY 04
B3: Sales Forecasting and Seasonality
B4: David Izzulhaq, Data Analyst | davidizzulhaq.github.io
B6: Business question
B7: Sales bounce around month to month. What is the real trend under the noise, when are the seasonal peaks, and what should we expect next?
B9: Dataset
B10: 1,096 daily sales records, Jun 2023 to May 2026 (36 months). The raw export had mixed dates, text-numbers, blanks and duplicates.
B12: Method
B13: 1) Clean and aggregate to monthly. 2) Estimate a linear trend and a seasonal index (which months run hot or cold). 3) Combine trend and seasonality into a model and a six-month forecast. 4) Measure accuracy with MAPE.
B15: Headline results
B16: Average month around Rp 4,830,488. The model captures the seasonal pattern and projects the next six months, with the error measured on history.
B18: How to read this file
... B22: Every formula is open. No black boxes.

Sheet Raw Data
A1: RAW DATA (as received, before cleaning)
A2: 1,110 rows. Real-world mess: mixed formats, text-numbers, duplicates, blanks, inconsistent casing.
A4: date | B4: sales
A5: 12/10/2024 | B5: 185130
A6: 24 Nov 2025 | B6: 167961
A7: 19 Oct 2024 | B7: 188199
A8: 18 Jan 2025 | B8: 177171
A9: 2024-04-28 | B9: 145274
A10: 07 Dec 2023 | B10: 162540
A11: 2024-09-04 | B11: Rp 131.163
A12: 2026-04-17 | B12: Rp 172.979
A13: 2024-06-02 | B13: 147269
A14: 2024-12-08 | B14: 197845
A15: 2026-01-17 | B15: 192002
A16: 2024-03-16 | B16: 143838
A17: 2023-10-27 | B17: Rp 108.633
A18: 2023-12-18 | B18: Rp 149.284
A19: 2024-03-27 | B19: Rp 118.553
A20: 2024-04-18 | B20: 130556
A21: 2026-02-18 | B21: 147161
A22: 2024-04-05 | B22: Rp 160.683
A23: 29 Sep 2024 | B23: 173799
A24: 2023-11-13 | B24: 135954
A25: 2024-08-11 | B25: 146464
A26: 2025-05-24 | B26: 302888
A27: 15/01/2025 | B27: 141139
A28: 20 Sep 2023 | B28: Rp 103.168
A29: 2025-10-19 | B29: 199669
A30: 2023-10-29 | B30: 116567
A31: 2025-03-07 | B31: 133604
A32: 2026-03-04 | B32: 159259
A33: 2024-03-26 | B33: 93744
A34: 23/08/2024 | B34: Rp 140.697
A35: 2023-12-11 | B35: 175158
A36: 03/02/2024 | B36: Rp 126.076
A37: 2024-05-18 | B37: Rp 223.976
A38: 2026-05-04 | B38: Rp 234.034
A39: 2025-12-18 | B39: 253335
A40: 2025-08-09 | B40: 185715
A41: 2024-01-05 | B41: 146149
...

Sheet Cleaning
A1: CLEANING LOG
A2: Every issue found, the fix applied, and how many rows it touched.
A4: Issue found | B4: Example | C4: Fix applied | D4: Rows affected
A5: Inconsistent date formats | B5: 01/06/2023 and 01 Jun 2023 | C5: Parsed to real Excel dates | D5: 284
A6: Sales stored as text | B6: 'Rp 140.480' | C6: Strip 'Rp' and dots, convert with VALUE() | D6: 219
A7: Missing sales days | B7: (blank cell) | C7: Interpolated from neighbouring days | D7: 21
A8: Duplicate day rows | B8: 2023-06-01 twice | C8: Removed exact duplicates | D8: 14
A9: Rows in, then after de-duplication | D9: 1,110 -> 1,096
A12: LIVE FORMULA DEMO (column C recomputes from column A)
A14: Raw value | B14: Formula (shown as text) | C14: Result (live)
A15: Rp 140.480 | B15: VALUE(SUBSTITUTE(SUBSTITUTE(A15,"Rp ",""),".","")) | C15: =VALUE(SUBSTITUTE(SUBSTITUTE(A15,"Rp ",""),".",""))
A16: 01/06/2023 | B16: DATEVALUE(A16) | C16: =DATEVALUE(A16)

Sheet Clean Data
A1: date | B1: sales | C1: month
A2: 45078 | B2: 140480 | C2: =TEXT($A2,"YYYY-MM")
A3: 45079 | B3: 140694 | C3: =TEXT($A3,"YYYY-MM")
A4: 45080 | B4: 155681 | C4: =TEXT($A4,"YYYY-MM")
A5: 45081 | B5: 145630 | C5: =TEXT($A5,"YYYY-MM")
A6: 45082 | B6: 132705 | C6: =TEXT($A6,"YYYY-MM")
A7: 45083 | B7: 132096 | C7: =TEXT($A7,"YYYY-MM")
A8: 45084 | B8: 145433 | C8: =TEXT($A8,"YYYY-MM")
A9: 45085 | B9: 145731 | C9: =TEXT($A9,"YYYY-MM")
A10: 45086 | B10: 139381 | C10: =TEXT($A10,"YYYY-MM")
A11: 45087 | B11: 173409 | C11: =TEXT($A11,"YYYY-MM")
A12: 45088 | B12: 166770 | C12: =TEXT($A12,"YYYY-MM")
A13: 45089 | B13: 117788 | C13: =TEXT($A13,"YYYY-MM")
... A1097: 46173 | B1097: 248281 | C1097: =TEXT($A1097,"YYYY-MM")

Sheet Analysis
A1: ANALYSIS (live trend, seasonality, and forecast referencing Clean Data) | L1: Slope/mo | M1: =SLOPE(D14:D49,A14:A49)
L2: Intercept | M2: =INTERCEPT(D14:D49,A14:A49)
A3: Key metrics | L3: Avg month | M3: =AVERAGE(D14:D49)
A4: Months of history | B4: =36 | L4: MAPE | M4: =AVERAGE(G14:G49)
A5: Average month | B5: =M3
A6: Trend per month | B6: =M1
A7: Forecast accuracy (MAPE) | B7: =M4
A8: Forecast 2026-06 | B8: =F50
A13: # | B13: Month | C13: CM | D13: Actual | E13: Trend | F13: Model | G13: Err % | H13: CM | I13: Seasonal idx
A14: 1 | B14: 2023-06 | C14: 6 | D14: =SUMIFS('Clean Data'!$B$2:$B$1097,'Clean Data'!$C$2:$C$1097,$B14) | E14: =$M$2+$M$1*A14 | F14: =E14*INDEX($I$14:$I$25,C14) | G14: =IFERROR(ABS(D14-F14)/D14,"") | H14: 1 | I14: =AVERAGEIFS($D$14:$D$49,$C$14:$C$49,H14)/$M$3
A15: 2 | B15: 2023-07 | C15: 7 | D15: =SUMIFS('Clean Data'!$B$2:$B$1097,'Clean Data'!$C$2:$C$1097,$B15) | E15: =$M$2+$M$1*A15 | F15: =E15*INDEX($I$14:$I$25,C15) | G15: =IFERROR(ABS(D15-F15)/D15,"") | H15: 2 | I15: =AVERAGEIFS($D$14:$D$49,$C$14:$C$49,H15)/$M$3
A16: 3 | B16: 2023-08 | C16: 8 | D16: =SUMIFS('Clean Data'!$B$2:$B$1097,'Clean Data'!$C$2:$C$1097,$B16) | E16: =$M$2+$M$1*A16 | F16: =E16*INDEX($I$14:$I$25,C16) | G16: =IFERROR(ABS(D16-F16)/D16,"") | H16: 3 | I16: =AVERAGEIFS($D$14:$D$49,$C$14:$C$49,H16)/$M$3
A17: 4 | B17: 2023-09 | C17: 9 | D17: =SUMIFS('Clean Data'!$B$2:$B$1097,'Clean Data'!$C$2:$C$1097,$B17) | E17: =$M$2+$M$1*A17 | F17: =E17*INDEX($I$14:$I$25,C17) | G17: =IFERROR(ABS(D17-F17)/D17,"") | H17: 4 | I17: =AVERAGEIFS($D$14:$D$49,$C$14:$C$49,H17)/$M$3
A18: 5 | B18: 2023-10 | C18: 10 | D18: =SUMIFS('Clean Data'!$B$2:$B$1097,'Clean Data'!$C$2:$C$1097,$B18) | E18: =$M$2+$M$1*A18 | F18: =E18*INDEX($I$14:$I$25,C18) | G18: =IFERROR(ABS(D18-F18)/D18,"") | H18: 5 | I18: =AVERAGEIFS($D$14:$D$49,$C$14:$C$49,H18)/$M$3
A19: 6 | B19: 2023-11 | C19: 11 | D19: =SUMIFS('Clean Data'!$B$2:$B$1097,'Clean Data'!$C$2:$C$1097,$B19) | E19: =$M$2+$M$1*A19 | F19: =E19*INDEX($I$14:$I$25,C19) | G19: =IFERROR(ABS(D19-F19)/D19,"") | H19: 6 | I19: =AVERAGEIFS($D$14:$D$49,$C$14:$C$49,H19)/$M$3
A20: 7 | B20: 2023-12 | C20: 12 | D20: =SUMIFS('Clean Data'!$B$2:$B$1097,'Clean Data'!$C$2:$C$1097,$B20) | E20: =$M$2+$M$1*A20 | F20: =E20*INDEX($I$14:$I$25,C20) | G20: =IFERROR(ABS(D20-F20)/D20,"") | H20: 7 | I20: =AVERAGEIFS($D$14:$D$49,$C$14:$C$49,H20)/$M$3
A21: 8 | B21: 2024-01 | C21: 1 | D21: =SUMIFS('Clean Data'!$B$2:$B$1097,'Clean Data'!$C$2:$C$1097,$B21) | E21: =$M$2+$M$1*A21 | F21: =E21*INDEX($I$14:$I$25,C21) | G21: =IFERROR(ABS(D21-F21)/D21,"") | H21: 8 | I21: =AVERAGEIFS($D$14:$D$49,$C$14:$C$49,H21)/$M$3
A22: 9 | B22: 2024-02 | C22: 2 | D22: =SUMIFS('Clean Data'!$B$2:$B$1097,'Clean Data'!$C$2:$C$1097,$B22) | E22: =$M$2+$M$1*A22 | F22: =E22*INDEX($I$14:$I$25,C22) | G22: =IFERROR(ABS(D22-F22)/D22,"") | H22: 9 | I22: =AVERAGEIFS($D$14:$D$49,$C$14:$C$49,H22)/$M$3
A23: 10 | B23: 2024-03 | C23: 3 | D23: =SUMIFS('Clean Data'!$B$2:$B$1097,'Clean Data'!$C$2:$C$1097,$B23) | E23: =$M$2+$M$1*A23 | F23: =E23*INDEX($I$14:$I$25,C23) | G23: =IFERROR(ABS(D23-F23)/D23,"") | H23: 10 | I23: =AVERAGEIFS($D$14:$D$49,$C$14:$C$49,H23)/$M$3
A24: 11 | B24: 2024-04 | C24: 4 | D24: =SUMIFS('Clean Data'!$B$2:$B$1097,'Clean Data'!$C$2:$C$1097,$B24) | E24: =$M$2+$M$1*A24 | F24: =E24*INDEX($I$14:$I$25,C24) | G24: =IFERROR(ABS(D24-F24)/D24,"") | H24: 11 | I24: =AVERAGEIFS($D$14:$D$49,$C$14:$C$49,H24)/$M$3
A25: 12 | B25: 2024-05 | C25: 5 | D25: =SUMIFS('Clean Data'!$B$2:$B$1097,'Clean Data'!$C$2:$C$1097,$B25) | E25: =$M$2+$M$1*A25 | F25: =E25*INDEX($I$14:$I$25,C25) | G25: =IFERROR(ABS(D25-F25)/D25,"") | H25: 12 | I25: =AVERAGEIFS($D$14:$D$49,$C$14:$C$49,H25)/$M$3
A26: 13 | B26: 2024-06 | C26: 6 | D26: =SUMIFS('Clean Data'!$B$2:$B$1097,'Clean Data'!$C$2:$C$1097,$B26) | E26: =$M$2+$M$1*A26 | F26: =E26*INDEX($I$14:$I$25,C26) | G26: =IFERROR(ABS(D26-F26)/D26,"")
A27: 14 | B27: 2024-07 | C27: 7 | D27: =SUMIFS('Clean Data'!$B$2:$B$1097,'Clean Data'!$C$2:$C$1097,$B27) | E27: =$M$2+$M$1*A27 | F27: =E27*INDEX($I$14:$I$25,C27) | G27: =IFERROR(ABS(D27-F27)/D27,"")
A28: 15 | B28: 2024-08 | C28: 8 | D28: =SUMIFS('Clean Data'!$B$2:$B$1097,'Clean Data'!$C$2:$C$1097,$B28) | E28: =$M$2+$M$1*A28 | F28: =E28*INDEX($I$14:$I$25,C28) | G28: =IFERROR(ABS(D28-F28)/D28,"")
A29: 16 | B29: 2024-09 | C29: 9 | D29: =SUMIFS('Clean Data'!$B$2:$B$1097,'Clean Data'!$C$2:$C$1097,$B29) | E29: =$M$2+$M$1*A29 | F29: =E29*INDEX($I$14:$I$25,C29) | G29: =IFERROR(ABS(D29-F29)/D29,"")
A30: 17 | B30: 2024-10 | C30: 10 | D30: =SUMIFS('Clean Data'!$B$2:$B$1097,'Clean Data'!$C$2:$C$1097,$B30) | E30: =$M$2+$M$1*A30 | F30: =E30*INDEX($I$14:$I$25,C30) | G30: =IFERROR(ABS(D30-F30)/D30,"")
A31: 18 | B31: 2024-11 | C31: 11 | D31: =SUMIFS('Clean Data'!$B$2:$B$1097,'Clean Data'!$C$2:$C$1097,$B31) | E31: =$M$2+$M$1*A31 | F31: =E31*INDEX($I$14:$I$25,C31) | G31: =IFERROR(ABS(D31-F31)/D31,"")
A32: 19 | B32: 2024-12 | C32: 12 | D32: =SUMIFS('Clean Data'!$B$2:$B$1097,'Clean Data'!$C$2:$C$1097,$B32) | E32: =$M$2+$M$1*A32 | F32: =E32*INDEX($I$14:$I$25,C32) | G32: =IFERROR(ABS(D32-F32)/D32,"")
A33: 20 | B33: 2025-01 | C33: 1 | D33: =SUMIFS('Clean Data'!$B$2:$B$1097,'Clean Data'!$C$2:$C$1097,$B33) | E33: =$M$2+$M$1*A33 | F33: =E33*INDEX($I$14:$I$25,C33) | G33: =IFERROR(ABS(D33-F33)/D33,"")
A34: 21 | B34: 2025-02 | C34: 2 | D34: =SUMIFS('Clean Data'!$B$2:$B$1097,'Clean Data'!$C$2:$C$1097,$B34) | E34: =$M$2+$M$1*A34 | F34: =E34*INDEX($I$14:$I$25,C34) | G34: =IFERROR(ABS(D34-F34)/D34,"")
A35: 22 | B35: 2025-03 | C35: 3 | D35: =SUMIFS('Clean Data'!$B$2:$B$1097,'Clean Data'!$C$2:$C$1097,$B35) | E35: =$M$2+$M$1*A35 | F35: =E35*INDEX($I$14:$I$25,C35) | G35: =IFERROR(ABS(D35-F35)/D35,"")
A36: 23 | B36: 2025-04 | C36: 4 | D36: =SUMIFS('Clean Data'!$B$2:$B$1097,'Clean Data'!$C$2:$C$1097,$B36) | E36: =$M$2+$M$1*A36 | F36: =E36*INDEX($I$14:$I$25,C36) | G36: =IFERROR(ABS(D36-F36)/D36,"")
A37: 24 | B37: 2025-05 | C37: 5 | D37: =SUMIFS('Clean Data'!$B$2:$B$1097,'Clean Data'!$C$2:$C$1097,$B37) | E37: =$M$2+$M$1*A37 | F37: =E37*INDEX($I$14:$I$25,C37) | G37: =IFERROR(ABS(D37-F37)/D37,"")
... A49: 36 | B49: 2026-05 | C49: 5 | D49: =SUMIFS('Clean Data'!$B$2:$B$1097,'Clean Data'!$C$2:$C$1097,$B49) | E49: =$M$2+$M$1*A49 | F49: =E49*INDEX($I$14:$I$25,C49) | G49: =IFERROR(ABS(D49-F49)/D49,"")
A50: 37 | B50: 2026-06 | C50: 6 | E50: =$M$2+$M$1*A50 | F50: =E50*INDEX($I$14:$I$25,C50)
A51: 38 | B51: 2026-07 | C51: 7 | E51: =$M$2+$M$1*A51 | F51: =E51*INDEX($I$14:$I$25,C51)
A52: 39 | B52: 2026-08 | C52: 8 | E52: =$M$2+$M$1*A52 | F52: =E52*INDEX($I$14:$I$25,C52)
A53: 40 | B53: 2026-09 | C53: 9 | E53: =$M$2+$M$1*A53 | F53: =E53*INDEX($I$14:$I$25,C53)
A54: 41 | B54: 2026-10 | C54: 10 | E54: =$M$2+$M$1*A54 | F54: =E54*INDEX($I$14:$I$25,C54)
A55: 42 | B55: 2026-11 | C55: 11 | E55: =$M$2+$M$1*A55 | F55: =E55*INDEX($I$14:$I$25,C55)

Sheet Dashboard
A1: DASHBOARD
A2: Sales Forecasting and Seasonality. Charts read live from Analysis. Same view as the web case study.
A4: Months | C4: Avg month | E4: Trend/mo | G4: MAPE | I4: Next: 2026-06 | K4: Seasonal peak
A5: =36 | C5: =Analysis!M3 | E5: =Analysis!M1 | G5: =Analysis!M4 | I5: =Analysis!F50 | K5: =INDEX(Analysis!H14:H25,MATCH(MAX(Analysis!I14:I25),Analysis!I14:I25,0))
A25: The model line tracks actual sales and continues past the last actual month as the six-month forecast.
A45: Months above 1.0 run hotter than average. Plan stock and staffing around the peaks.
A48: Recommendations
A49: - Use the forecast to set monthly targets and pre-order stock for the seasonal peaks.
A50: - Treat the MAPE as the expected error band around each forecast number.
A51: - Revisit the model each month as new actuals arrive; the formulas update automatically.
A52: - Investigate any month where actual falls far outside the model line.

Sheet VBA
A1: VBA AUTOMATION (also provided as Module1.bas next to this file)
A2: Paste into the VBA editor (Alt+F11, Insert, Module) to normalise a fresh raw paste.
A4: Attribute VB_Name = "Module1"
A5: ' One-click cleaner for the "Raw Data" sheet: converts "Rp 1.234" sales text to numbers.
A6: Sub CleanRawData()
A7: Dim ws As Worksheet, lastRow As Long, r As Long, v As String
A8: Set ws = ThisWorkbook.Sheets("Raw Data")
A9: lastRow = ws.Cells(ws.Rows.Count, 1).End(xlUp).Row
A10: Application.ScreenUpdating = False
A11: For r = 5 To lastRow
A12: v = CStr(ws.Cells(r, 2).Value)
A13: If InStr(1, v, "Rp", vbTextCompare) > 0 Then
... A20: End Sub
