Workbook

Sheet Read Me
B2: CASE STUDY 01
B3: E-commerce Sales and Customer Analysis
B4: David Izzulhaq, Data Analyst | davidizzulhaq.github.io
B6: Business question
B7: Where does revenue come from, which customers keep the business alive, and who is slipping away? Management had four spreadsheets that never reconciled.
B9: Dataset
B10: 1,564 order lines, Jan 2025 to Jun 2026. The raw export arrived with mixed date formats, text-numbers, duplicates, casing noise and blanks.
B12: Method
B13: 1) Profile the raw export. 2) Clean and standardise. 3) Model revenue by month, channel, category and run a full RFM customer segmentation and a Pareto product analysis with open formulas. 4) Summarise into a dashboard with recommendations.
B15: Headline results
B16: Total revenue Rp 496,541,000. Top channel: Shopee. A Pareto core of products drives most sales. RFM shows which customers are Champions and which are slipping to At risk.
B18: How to read this file
... B22: Every formula is open. No black boxes.

Sheet Raw Data
A1: RAW DATA (as received, before cleaning)
A2: 1,582 rows. Mixed date formats, 'Rp ...' text, duplicates, blanks, inconsistent casing.
A4: order_id | B4: order_date | C4: customer_id | D4: cust_type | E4: channel | F4: region | G4: category | H4: product | I4: qty | J4: unit_price | K4: revenue
A5: INV-70654 | B5: 2025-11-21 | C5: C1179 | D5: loyal | E5: TikTok Shop | F5: Jabodetabek | G5: Elektronik | H5: Smartwatch | I5: 2 | J5: 450000 | K5: Rp 900.000
A6: INV-71047 | B6: 05 May 2026 | C6: C1296 | D6: loyal | E6: TikTok Shop | F6: Jawa Tengah | G6: Elektronik | H6: Smartwatch | I6: 1 | J6: 450000 | K6: 450000
A7: INV-71542 | B7: 2025-03-23 | C7: C1425 | D7: loyal | E7: Tokopedia | F7: Jawa Barat | G7: Kecantikan | H7: Masker Wajah (5s) | I7: 1 | J7: 55000 | K7: 40000
A8: INV-70219 | B8: 19/11/2025 | C8: C1061 | D8: occasional | E8: TikTok Shop | F8: Jabodetabek | G8: Rumah Tangga | H8: Set Wadah Kedap | I8: 1 | J8: 135000 | K8: 135000
A9: INV-70103 | B9: 2025-12-04 | C9: C1029 | D9: champion | E9: Tokopedia | F9: Jawa Tengah | G9: Rumah Tangga | H9: Diffuser Aroma | I9: 4 | J9: 195000 | K9: 780000
A10: INV-71397 | B10: 2026-03-26 | C10: C1386 | D10: loyal | E10: Offline Store | F10: Lainnya | G10: Rumah Tangga | H10: Diffuser Aroma | I10: 4 | J10: 195000 | K10: 780000
A11: INV-70701 | B11: 2025-06-03 | C11: C1195 | D11: champion | E11: Shopee | G11: Fashion | H11: Celana Chino | I11: 4 | J11: 195000 | K11: 780000
A12: INV-70125 | B12: 04 May 2026 | C12: C1038 | D12: champion | E12: SHOPEE | F12: Jabodetabek | G12: Rumah Tangga | H12: Set Wadah Kedap | I12: 1 | J12: 135000 | K12: Rp 135.000
A13: INV-70538 | B13: 2026-04-21 | C13: C1149 | D13: loyal | E13: Offline store | F13: Lainnya | G13: Rumah Tangga | H13: Set Wadah Kedap | I13: 4 | J13: 135000 | K13: 540000
A14: INV-70730 | B14: 2026-04-22 | C14: C1206 | D14: regular | E14: Offline Store | F14: Jabodetabek | G14: Rumah Tangga | H14: Set Wadah Kedap | I14: 3 | J14: 135000 | K14: 405000
A15: INV-71440 | B15: 2025-03-12 | C15: C1396 | D15: loyal | E15: Tiktok Shop | F15: Jabodetabek | G15: Elektronik | H15: Webcam HD | I15: 3 | J15: 210000 | K15: 630000
A16: INV-71549 | B16: 2025-10-23 | C16: C1427 | D16: occasional | E16: TikTok Shop | F16: Sumatera | G16: Elektronik | H16: Keyboard Mekanik | I16: 2 | J16: 380000 | K16: 760000
A17: INV-70357 | B17: 2026-01-21 | C17: C1097 | D17: regular | E17: Shopee | F17: Jabodetabek | G17: Rumah Tangga | H17: Set Wadah Kedap | I17: 3 | J17: 135000 | K17: Rp 405.000
A18: INV-70619 | B18: 2025-02-01 | C18: C1169 | D18: occasional | E18: Shopee | F18: Jabodetabek | G18: Rumah Tangga | H18: Set Wadah Kedap | I18: -1 | J18: 135000 | K18: 135000
A19: INV-70948 | B19: 2025-12-02 | C19: C1268 | D19: regular | E19: Shopee | F19: Sumatera | G19: Elektronik | H19: Smartwatch | I19: 4 | J19: 450000 | K19: 1800000
A20: INV-71062 | B20: 02/01/2025 | C20: C1301 | D20: regular | E20: tokopedia | F20: Jabodetabek | G20: Rumah Tangga | H20: Set Wadah Kedap | I20: 1 | J20: 135000 | K20: 135000
A21: INV-70495 | B21: 2025-08-27 | C21: C1139 | D21: champion | E21: SHOPEE | F21: Jawa Tengah | G21: Rumah Tangga | H21: Organizer Laci | I21: 1 | J21: 78000 | K21: 78000
A22: INV-70838 | B22: 2025-02-02 | C22: C1236 | D22: onetime | E22: shopee | F22: Jawa Tengah | G22: Rumah Tangga | H22: Set Wadah Kedap | I22: 1 | J22: 135000 | K22: 135000
A23: INV-70167 | B23: 2026-04-26 | C23: C1049 | D23: champion | E23: Tokopedia | F23: Jawa Timur | G23: Fashion | H23: Kaos Premium | I23: 2 | J23: 95000 | K23: Rp 190.000
A24: INV-70852 | B24: 21/01/2025 | C24: C1240 | D24: loyal | E24: Shopee | F24: Lainnya | G24: Fashion | H24: Celana Chino | I24: 3 | J24: 195000 | K24: 585000
A25: INV-70791 | B25: 02/04/2026 | C25: C1222 | D25: loyal | E25: tiktok shop | F25: Jabodetabek | G25: Kecantikan | H25: Masker Wajah (5s) | I25: 1 | J25: 55000 | K25: 55000
A26: INV-71370 | B26: 2026-04-06 | C26: C1378 | D26: regular | E26: shopee | F26: Jabodetabek | G26: Elektronik | H26: Smartwatch | I26: 1 | J26: 450000 | K26: 450000
A27: INV-71054 | B27: 21 Aug 2025 | C27: C1299 | D27: occasional | E27: TikTok Shop | F27: Sumatera | G27: Rumah Tangga | H27: Set Wadah Kedap | I27: 3 | J27: 135000 | K27: 405000
A28: INV-70430 | B28: 2025-10-25 | C28: C1122 | D28: loyal | E28: tokopedia | F28: Jabodetabek | G28: Rumah Tangga | H28: Set Wadah Kedap | I28: 1 | J28: 135000 | K28: 135000
A29: INV-71543 | B29: 2026-02-18 | C29: C1425 | D29: loyal | E29: Shopee | F29: Jabodetabek | G29: Elektronik | H29: Smartwatch | I29: 1 | J29: 450000 | K29: 450000
A30: INV-71344 | B30: 2025-08-07 | C30: C1369 | D30: loyal | E30: tiktok shop | F30: Jabodetabek | G30: Rumah Tangga | H30: Organizer Laci | I30: 2 | J30: 78000 | K30: 156000
A31: INV-70263 | B31: 2025-04-26 | C31: C1074 | D31: regular | E31: Tokopedia | F31: Sumatera | G31: Kecantikan | H31: Masker Wajah (5s) | I31: 1 | J31: 55000 | K31: 55000
A32: INV-71281 | B32: 2026-04-27 | C32: C1358 | D32: champion | E32: Offline store | F32: Lainnya | G32: rumah tangga | H32: Set Wadah Kedap | I32: 2 | J32: 135000 | K32: 270000
A33: INV-70743 | B33: 05 Feb 2026 | C33: C1207 | D33: loyal | E33: TIKTOK SHOP | F33: Sumatera | G33: Makanan | H33: Madu Hutan 250ml | I33: 2 | J33: 110000 | K33: Rp 220.000
A34: INV-70429 | B34: 06/06/2025 | C34: C1122 | D34: loyal | E34: Offline Store | F34: Jawa Barat | G34: Fashion | H34: Celana Chino | I34: 1 | J34: 195000 | K34: 195000
A35: INV-71165 | B35: 2026-02-01 | C35: C1329 | D35: regular | E35: TikTok Shop | F35: Jabodetabek | G35: Rumah Tangga | H35: Set Wadah Kedap | I35: 2 | J35: 135000 | K35: 270000
A36: INV-70381 | B36: 2025-01-10 | C36: C1110 | D36: loyal | E36: Tokopedia | F36: Sumatera | G36: Rumah Tangga | H36: Set Wadah Kedap | I36: 1 | J36: 135000 | K36: 135000
A37: INV-70995 | B37: 2025-02-07 | C37: C1287 | D37: champion | E37: Tokopedia | F37: Sumatera | G37: Rumah Tangga | H37: Lampu Meja LED | I37: 2 | J37: 165000 | K37: 330000
A38: INV-71190 | B38: 2025-11-24 | C38: C1335 | D38: regular | E38: Shopee | F38: Jawa Barat | G38: kecantikan | H38: Masker Wajah (5s) | I38: 2 | J38: 55000 | K38: 110000
A39: INV-70527 | B39: 05 Nov 2025 | C39: C1146 | D39: occasional | E39: Shopee | F39: Jawa Timur | G39: Makanan | H39: Madu Hutan 250ml | I39: 4 | J39: 110000 | K39: 440000
A40: INV-70465 | B40: 2026-04-18 | C40: C1133 | D40: regular | E40: Tokopedia | F40: Jawa Timur | G40: Rumah Tangga | H40: Set Wadah Kedap | I40: 1 | J40: 135000 | K40: 135000
A41: INV-70572 | B41: 2025-03-01 | C41: C1156 | D41: champion | E41: Offline Store | F41: Jawa Timur | G41: Rumah Tangga | H41: Set Wadah Kedap | I41: 1 | J41: 135000 | K41: 135000
...

Sheet Cleaning
A1: CLEANING LOG
A2: Every issue found, the fix applied, and how many rows it touched.
A4: Issue found | B4: Example | C4: Fix applied | D4: Rows affected
A5: Inconsistent date formats | B5: 01/03/2025 and 15 Mar 2025 | C5: Parsed all to real Excel dates | D5: 437
A6: Channel: mixed case and stray spaces | B6: 'shopee ', 'TIKTOK SHOP' | C6: TRIM + PROPER normalisation | D6: 469
A7: Category: inconsistent casing | B7: 'kecantikan', 'makanan' | C7: PROPER case normalisation | D7: 187
A8: Revenue stored as text | B8: 'Rp 156.000' | C8: Strip 'Rp' and dots, convert with VALUE() | D8: 312
A9: Missing region | B9: (blank cell) | C9: Filled with 'Lainnya' (Other) | D9: 31
A10: Invalid quantity (blank or negative) | B10: blank, -2 | C10: Flagged and corrected from order lines | D10: 12
A11: Duplicate order rows | B11: INV-70016 appears twice | C11: Removed exact duplicates | D11: 18
A12: Revenue not equal to qty x unit_price | B12: off by 12.000 | C12: Recomputed from qty x unit_price | D12: 9
A13: Rows in, then after de-duplication | D13: 1,582 -> 1,564
A16: LIVE FORMULA DEMO (the actual cleaning formulas, shown working)
A17: Column C is live and recomputes from column A.
A19: Raw value | B19: Formula (shown as text) | C19: Result (live)
A20: shopee | B20: PROPER(TRIM(A20)) | C20: =PROPER(TRIM(A20))
A21: TIKTOK SHOP | B21: PROPER(TRIM(A21)) | C21: =PROPER(TRIM(A21))
A22: Rp 156.000 | B22: VALUE(SUBSTITUTE(SUBSTITUTE(A22,"Rp ",""),".","")) | C22: =VALUE(SUBSTITUTE(SUBSTITUTE(A22,"Rp ",""),".",""))
A23: 01/03/2025 | B23: DATEVALUE(A23) | C23: =DATEVALUE(A23)
A24: kecantikan | B24: PROPER(A24) | C24: =PROPER(A24)

Sheet Clean Data
A1: order_id | B1: order_date | C1: customer_id | D1: cust_type | E1: channel | F1: region | G1: category | H1: product | I1: qty | J1: unit_price | K1: revenue | L1: month
A2: INV-70016 | B2: 45658 | C2: C1003 | D2: regular | E2: Tokopedia | F2: Jawa Barat | G2: Rumah Tangga | H2: Organizer Laci | I2: 2 | J2: 78000 | K2: 156000 | L2: =IF($B2="","",TEXT($B2,"YYYY-MM"))
A3: INV-71101 | B3: 45658 | C3: C1309 | D3: regular | E3: TikTok Shop | F3: Jabodetabek | G3: Makanan | H3: Granola 500g | I3: 1 | J3: 92000 | K3: 92000 | L3: =IF($B3="","",TEXT($B3,"YYYY-MM"))
A4: INV-71102 | B4: 45658 | C4: C1309 | D4: regular | E4: Shopee | F4: Jabodetabek | G4: Kecantikan | H4: Masker Wajah (5s) | I4: 2 | J4: 55000 | K4: 110000 | L4: =IF($B4="","",TEXT($B4,"YYYY-MM"))
A5: INV-71176 | B5: 45658 | C5: C1334 | D5: champion | E5: TikTok Shop | F5: Sumatera | G5: Kecantikan | H5: Masker Wajah (5s) | I5: 1 | J5: 55000 | K5: 55000 | L5: =IF($B5="","",TEXT($B5,"YYYY-MM"))
A6: INV-71062 | B6: 45659 | C6: C1301 | D6: regular | E6: Tokopedia | F6: Jabodetabek | G6: Rumah Tangga | H6: Set Wadah Kedap | I6: 1 | J6: 135000 | K6: 135000 | L6: =IF($B6="","",TEXT($B6,"YYYY-MM"))
A7: INV-71377 | B7: 45659 | C7: C1380 | D7: onetime | E7: TikTok Shop | F7: Jabodetabek | G7: Elektronik | H7: Webcam HD | I7: 2 | J7: 210000 | K7: 420000 | L7: =IF($B7="","",TEXT($B7,"YYYY-MM"))
A8: INV-70336 | B8: 45660 | C8: C1093 | D8: champion | E8: Shopee | F8: Jabodetabek | G8: Elektronik | H8: Earbuds TWS | I8: 4 | J8: 265000 | K8: 1060000 | L8: =IF($B8="","",TEXT($B8,"YYYY-MM"))
A9: INV-70129 | B9: 45660 | C9: C1038 | D9: champion | E9: TikTok Shop | F9: Jawa Barat | G9: Kecantikan | H9: Masker Wajah (5s) | I9: 4 | J9: 55000 | K9: 220000 | L9: =IF($B9="","",TEXT($B9,"YYYY-MM"))
A10: INV-70988 | B10: 45660 | C10: C1284 | D10: occasional | E10: Offline Store | F10: Jawa Tengah | G10: Fashion | H10: Celana Chino | I10: 4 | J10: 195000 | K10: 780000 | L10: =IF($B10="","",TEXT($B10,"YYYY-MM"))
A11: INV-70969 | B11: 45661 | C11: C1277 | D11: onetime | E11: Offline Store | F11: Jabodetabek | G11: Makanan | H11: Granola 500g | I11: 4 | J11: 92000 | K11: 368000 | L11: =IF($B11="","",TEXT($B11,"YYYY-MM"))
A12: INV-70326 | B12: 45662 | C12: C1090 | D12: champion | E12: Shopee | F12: Jabodetabek | G12: Kecantikan | H12: Masker Wajah (5s) | I12: 1 | J12: 55000 | K12: 55000 | L12: =IF($B12="","",TEXT($B12,"YYYY-MM"))
A13: INV-71044 | B13: 45662 | C13: C1295 | D13: regular | E13: TikTok Shop | F13: Jabodetabek | G13: Rumah Tangga | H13: Set Wadah Kedap | I13: 3 | J13: 135000 | K13: 405000 | L13: =IF($B13="","",TEXT($B13,"YYYY-MM"))
... A1565: INV-70311 | B1565: 46200 | C1565: C1088 | D1565: champion | E1565: Offline Store | F1565: Jawa Tengah | G1565: Rumah Tangga | H1565: Organizer Laci | I1565: 2 | J1565: 78000 | K1565: 156000 | L1565: =IF($B1565="","",TEXT($B1565,"YYYY-MM"))

Sheet RFM
A1: RFM CUSTOMER SCORING (Recency, Frequency, Monetary, live formulas)
A2: Each customer scored 1 to 5 on how recently and how often they buy and how much they spend, then bucketed into a segment.
A4: Snapshot date | B4: =MAX('Clean Data'!$B$2:$B$1565)+1 | J4: Scoring cutoffs (quintiles)
J5: Percentile | K5: Recency | L5: Frequency | M5: Monetary
J6: P20 | K6: =PERCENTILE(RFM!$B$8:$B$437,0.2) | L6: =PERCENTILE(RFM!$C$8:$C$437,0.2) | M6: =PERCENTILE(RFM!$D$8:$D$437,0.2)
A7: customer_id | B7: Recency (days) | C7: Frequency | D7: Monetary | E7: R | F7: F | G7: M | H7: Segment | J7: P40 | K7: =PERCENTILE(RFM!$B$8:$B$437,0.4) | L7: =PERCENTILE(RFM!$C$8:$C$437,0.4) | M7: =PERCENTILE(RFM!$D$8:$D$437,0.4)
A8: C1000 | B8: =$B$4-_xlfn.MAXIFS('Clean Data'!$B$2:$B$1565,'Clean Data'!$C$2:$C$1565,$A8) | C8: =COUNTIF('Clean Data'!$C$2:$C$1565,$A8) | D8: =SUMIF('Clean Data'!$C$2:$C$1565,$A8,'Clean Data'!$K$2:$K$1565) | E8: =IF(B8<=$K$6,5,IF(B8<=$K$7,4,IF(B8<=$K$8,3,IF(B8<=$K$9,2,1)))) | F8: =IF(C8>=$L$9,5,IF(C8>=$L$8,4,IF(C8>=$L$7,3,IF(C8>=$L$6,2,1)))) | G8: =IF(D8>=$M$9,5,IF(D8>=$M$8,4,IF(D8>=$M$7,3,IF(D8>=$M$6,2,1)))) | H8: =IF(AND(E8>=4,F8>=4),"Champions",IF(AND(E8>=3,F8>=3),"Loyal",IF(AND(E8>=4,F8<=2),"New customers",IF(AND(E8=3,F8<=2),"Potential",IF(AND(E8<=2,F8>=3),"At risk","Inactive"))))) | J8: P60 | K8: =PERCENTILE(RFM!$B$8:$B$437,0.6) | L8: =PERCENTILE(RFM!$C$8:$C$437,0.6) | M8: =PERCENTILE(RFM!$D$8:$D$437,0.6)
A9: C1001 | B9: =$B$4-_xlfn.MAXIFS('Clean Data'!$B$2:$B$1565,'Clean Data'!$C$2:$C$1565,$A9) | C9: =COUNTIF('Clean Data'!$C$2:$C$1565,$A9) | D9: =SUMIF('Clean Data'!$C$2:$C$1565,$A9,'Clean Data'!$K$2:$K$1565) | E9: =IF(B9<=$K$6,5,IF(B9<=$K$7,4,IF(B9<=$K$8,3,IF(B9<=$K$9,2,1)))) | F9: =IF(C9>=$L$9,5,IF(C9>=$L$8,4,IF(C9>=$L$7,3,IF(C9>=$L$6,2,1)))) | G9: =IF(D9>=$M$9,5,IF(D9>=$M$8,4,IF(D9>=$M$7,3,IF(D9>=$M$6,2,1)))) | H9: =IF(AND(E9>=4,F9>=4),"Champions",IF(AND(E9>=3,F9>=3),"Loyal",IF(AND(E9>=4,F9<=2),"New customers",IF(AND(E9=3,F9<=2),"Potential",IF(AND(E9<=2,F9>=3),"At risk","Inactive"))))) | J9: P80 | K9: =PERCENTILE(RFM!$B$8:$B$437,0.8) | L9: =PERCENTILE(RFM!$C$8:$C$437,0.8) | M9: =PERCENTILE(RFM!$D$8:$D$437,0.8)
A10: C1002 | B10: =$B$4-_xlfn.MAXIFS('Clean Data'!$B$2:$B$1565,'Clean Data'!$C$2:$C$1565,$A10) | C10: =COUNTIF('Clean Data'!$C$2:$C$1565,$A10) | D10: =SUMIF('Clean Data'!$C$2:$C$1565,$A10,'Clean Data'!$K$2:$K$1565) | E10: =IF(B10<=$K$6,5,IF(B10<=$K$7,4,IF(B10<=$K$8,3,IF(B10<=$K$9,2,1)))) | F10: =IF(C10>=$L$9,5,IF(C10>=$L$8,4,IF(C10>=$L$7,3,IF(C10>=$L$6,2,1)))) | G10: =IF(D10>=$M$9,5,IF(D10>=$M$8,4,IF(D10>=$M$7,3,IF(D10>=$M$6,2,1)))) | H10: =IF(AND(E10>=4,F10>=4),"Champions",IF(AND(E10>=3,F10>=3),"Loyal",IF(AND(E10>=4,F10<=2),"New customers",IF(AND(E10=3,F10<=2),"Potential",IF(AND(E10<=2,F10>=3),"At risk","Inactive")))))
A11: C1003 | B11: =$B$4-_xlfn.MAXIFS('Clean Data'!$B$2:$B$1565,'Clean Data'!$C$2:$C$1565,$A11) | C11: =COUNTIF('Clean Data'!$C$2:$C$1565,$A11) | D11: =SUMIF('Clean Data'!$C$2:$C$1565,$A11,'Clean Data'!$K$2:$K$1565) | E11: =IF(B11<=$K$6,5,IF(B11<=$K$7,4,IF(B11<=$K$8,3,IF(B11<=$K$9,2,1)))) | F11: =IF(C11>=$L$9,5,IF(C11>=$L$8,4,IF(C11>=$L$7,3,IF(C11>=$L$6,2,1)))) | G11: =IF(D11>=$M$9,5,IF(D11>=$M$8,4,IF(D11>=$M$7,3,IF(D11>=$M$6,2,1)))) | H11: =IF(AND(E11>=4,F11>=4),"Champions",IF(AND(E11>=3,F11>=3),"Loyal",IF(AND(E11>=4,F11<=2),"New customers",IF(AND(E11=3,F11<=2),"Potential",IF(AND(E11<=2,F11>=3),"At risk","Inactive")))))
A12: C1004 | B12: =$B$4-_xlfn.MAXIFS('Clean Data'!$B$2:$B$1565,'Clean Data'!$C$2:$C$1565,$A12) | C12: =COUNTIF('Clean Data'!$C$2:$C$1565,$A12) | D12: =SUMIF('Clean Data'!$C$2:$C$1565,$A12,'Clean Data'!$K$2:$K$1565) | E12: =IF(B12<=$K$6,5,IF(B12<=$K$7,4,IF(B12<=$K$8,3,IF(B12<=$K$9,2,1)))) | F12: =IF(C12>=$L$9,5,IF(C12>=$L$8,4,IF(C12>=$L$7,3,IF(C12>=$L$6,2,1)))) | G12: =IF(D12>=$M$9,5,IF(D12>=$M$8,4,IF(D12>=$M$7,3,IF(D12>=$M$6,2,1)))) | H12: =IF(AND(E12>=4,F12>=4),"Champions",IF(AND(E12>=3,F12>=3),"Loyal",IF(AND(E12>=4,F12<=2),"New customers",IF(AND(E12=3,F12<=2),"Potential",IF(AND(E12<=2,F12>=3),"At risk","Inactive")))))
A13: C1005 | B13: =$B$4-_xlfn.MAXIFS('Clean Data'!$B$2:$B$1565,'Clean Data'!$C$2:$C$1565,$A13) | C13: =COUNTIF('Clean Data'!$C$2:$C$1565,$A13) | D13: =SUMIF('Clean Data'!$C$2:$C$1565,$A13,'Clean Data'!$K$2:$K$1565) | E13: =IF(B13<=$K$6,5,IF(B13<=$K$7,4,IF(B13<=$K$8,3,IF(B13<=$K$9,2,1)))) | F13: =IF(C13>=$L$9,5,IF(C13>=$L$8,4,IF(C13>=$L$7,3,IF(C13>=$L$6,2,1)))) | G13: =IF(D13>=$M$9,5,IF(D13>=$M$8,4,IF(D13>=$M$7,3,IF(D13>=$M$6,2,1)))) | H13: =IF(AND(E13>=4,F13>=4),"Champions",IF(AND(E13>=3,F13>=3),"Loyal",IF(AND(E13>=4,F13<=2),"New customers",IF(AND(E13=3,F13<=2),"Potential",IF(AND(E13<=2,F13>=3),"At risk","Inactive")))))
A14: C1006 | B14: =$B$4-_xlfn.MAXIFS('Clean Data'!$B$2:$B$1565,'Clean Data'!$C$2:$C$1565,$A14) | C14: =COUNTIF('Clean Data'!$C$2:$C$1565,$A14) | D14: =SUMIF('Clean Data'!$C$2:$C$1565,$A14,'Clean Data'!$K$2:$K$1565) | E14: =IF(B14<=$K$6,5,IF(B14<=$K$7,4,IF(B14<=$K$8,3,IF(B14<=$K$9,2,1)))) | F14: =IF(C14>=$L$9,5,IF(C14>=$L$8,4,IF(C14>=$L$7,3,IF(C14>=$L$6,2,1)))) | G14: =IF(D14>=$M$9,5,IF(D14>=$M$8,4,IF(D14>=$M$7,3,IF(D14>=$M$6,2,1)))) | H14: =IF(AND(E14>=4,F14>=4),"Champions",IF(AND(E14>=3,F14>=3),"Loyal",IF(AND(E14>=4,F14<=2),"New customers",IF(AND(E14=3,F14<=2),"Potential",IF(AND(E14<=2,F14>=3),"At risk","Inactive")))))
A15: C1007 | B15: =$B$4-_xlfn.MAXIFS('Clean Data'!$B$2:$B$1565,'Clean Data'!$C$2:$C$1565,$A15) | C15: =COUNTIF('Clean Data'!$C$2:$C$1565,$A15) | D15: =SUMIF('Clean Data'!$C$2:$C$1565,$A15,'Clean Data'!$K$2:$K$1565) | E15: =IF(B15<=$K$6,5,IF(B15<=$K$7,4,IF(B15<=$K$8,3,IF(B15<=$K$9,2,1)))) | F15: =IF(C15>=$L$9,5,IF(C15>=$L$8,4,IF(C15>=$L$7,3,IF(C15>=$L$6,2,1)))) | G15: =IF(D15>=$M$9,5,IF(D15>=$M$8,4,IF(D15>=$M$7,3,IF(D15>=$M$6,2,1)))) | H15: =IF(AND(E15>=4,F15>=4),"Champions",IF(AND(E15>=3,F15>=3),"Loyal",IF(AND(E15>=4,F15<=2),"New customers",IF(AND(E15=3,F15<=2),"Potential",IF(AND(E15<=2,F15>=3),"At risk","Inactive")))))
A16: C1008 | B16: =$B$4-_xlfn.MAXIFS('Clean Data'!$B$2:$B$1565,'Clean Data'!$C$2:$C$1565,$A16) | C16: =COUNTIF('Clean Data'!$C$2:$C$1565,$A16) | D16: =SUMIF('Clean Data'!$C$2:$C$1565,$A16,'Clean Data'!$K$2:$K$1565) | E16: =IF(B16<=$K$6,5,IF(B16<=$K$7,4,IF(B16<=$K$8,3,IF(B16<=$K$9,2,1)))) | F16: =IF(C16>=$L$9,5,IF(C16>=$L$8,4,IF(C16>=$L$7,3,IF(C16>=$L$6,2,1)))) | G16: =IF(D16>=$M$9,5,IF(D16>=$M$8,4,IF(D16>=$M$7,3,IF(D16>=$M$6,2,1)))) | H16: =IF(AND(E16>=4,F16>=4),"Champions",IF(AND(E16>=3,F16>=3),"Loyal",IF(AND(E16>=4,F16<=2),"New customers",IF(AND(E16=3,F16<=2),"Potential",IF(AND(E16<=2,F16>=3),"At risk","Inactive")))))
A17: C1009 | B17: =$B$4-_xlfn.MAXIFS('Clean Data'!$B$2:$B$1565,'Clean Data'!$C$2:$C$1565,$A17) | C17: =COUNTIF('Clean Data'!$C$2:$C$1565,$A17) | D17: =SUMIF('Clean Data'!$C$2:$C$1565,$A17,'Clean Data'!$K$2:$K$1565) | E17: =IF(B17<=$K$6,5,IF(B17<=$K$7,4,IF(B17<=$K$8,3,IF(B17<=$K$9,2,1)))) | F17: =IF(C17>=$L$9,5,IF(C17>=$L$8,4,IF(C17>=$L$7,3,IF(C17>=$L$6,2,1)))) | G17: =IF(D17>=$M$9,5,IF(D17>=$M$8,4,IF(D17>=$M$7,3,IF(D17>=$M$6,2,1)))) | H17: =IF(AND(E17>=4,F17>=4),"Champions",IF(AND(E17>=3,F17>=3),"Loyal",IF(AND(E17>=4,F17<=2),"New customers",IF(AND(E17=3,F17<=2),"Potential",IF(AND(E17<=2,F17>=3),"At risk","Inactive")))))
A18: C1010 | B18: =$B$4-_xlfn.MAXIFS('Clean Data'!$B$2:$B$1565,'Clean Data'!$C$2:$C$1565,$A18) | C18: =COUNTIF('Clean Data'!$C$2:$C$1565,$A18) | D18: =SUMIF('Clean Data'!$C$2:$C$1565,$A18,'Clean Data'!$K$2:$K$1565) | E18: =IF(B18<=$K$6,5,IF(B18<=$K$7,4,IF(B18<=$K$8,3,IF(B18<=$K$9,2,1)))) | F18: =IF(C18>=$L$9,5,IF(C18>=$L$8,4,IF(C18>=$L$7,3,IF(C18>=$L$6,2,1)))) | G18: =IF(D18>=$M$9,5,IF(D18>=$M$8,4,IF(D18>=$M$7,3,IF(D18>=$M$6,2,1)))) | H18: =IF(AND(E18>=4,F18>=4),"Champions",IF(AND(E18>=3,F18>=3),"Loyal",IF(AND(E18>=4,F18<=2),"New customers",IF(AND(E18=3,F18<=2),"Potential",IF(AND(E18<=2,F18>=3),"At risk","Inactive")))))
A19: C1011 | B19: =$B$4-_xlfn.MAXIFS('Clean Data'!$B$2:$B$1565,'Clean Data'!$C$2:$C$1565,$A19) | C19: =COUNTIF('Clean Data'!$C$2:$C$1565,$A19) | D19: =SUMIF('Clean Data'!$C$2:$C$1565,$A19,'Clean Data'!$K$2:$K$1565) | E19: =IF(B19<=$K$6,5,IF(B19<=$K$7,4,IF(B19<=$K$8,3,IF(B19<=$K$9,2,1)))) | F19: =IF(C19>=$L$9,5,IF(C19>=$L$8,4,IF(C19>=$L$7,3,IF(C19>=$L$6,2,1)))) | G19: =IF(D19>=$M$9,5,IF(D19>=$M$8,4,IF(D19>=$M$7,3,IF(D19>=$M$6,2,1)))) | H19: =IF(AND(E19>=4,F19>=4),"Champions",IF(AND(E19>=3,F19>=3),"Loyal",IF(AND(E19>=4,F19<=2),"New customers",IF(AND(E19=3,F19<=2),"Potential",IF(AND(E19<=2,F19>=3),"At risk","Inactive")))))
A20: C1012 | B20: =$B$4-_xlfn.MAXIFS('Clean Data'!$B$2:$B$1565,'Clean Data'!$C$2:$C$1565,$A20) | C20: =COUNTIF('Clean Data'!$C$2:$C$1565,$A20) | D20: =SUMIF('Clean Data'!$C$2:$C$1565,$A20,'Clean Data'!$K$2:$K$1565) | E20: =IF(B20<=$K$6,5,IF(B20<=$K$7,4,IF(B20<=$K$8,3,IF(B20<=$K$9,2,1)))) | F20: =IF(C20>=$L$9,5,IF(C20>=$L$8,4,IF(C20>=$L$7,3,IF(C20>=$L$6,2,1)))) | G20: =IF(D20>=$M$9,5,IF(D20>=$M$8,4,IF(D20>=$M$7,3,IF(D20>=$M$6,2,1)))) | H20: =IF(AND(E20>=4,F20>=4),"Champions",IF(AND(E20>=3,F20>=3),"Loyal",IF(AND(E20>=4,F20<=2),"New customers",IF(AND(E20=3,F20<=2),"Potential",IF(AND(E20<=2,F20>=3),"At risk","Inactive")))))
A21: C1013 | B21: =$B$4-_xlfn.MAXIFS('Clean Data'!$B$2:$B$1565,'Clean Data'!$C$2:$C$1565,$A21) | C21: =COUNTIF('Clean Data'!$C$2:$C$1565,$A21) | D21: =SUMIF('Clean Data'!$C$2:$C$1565,$A21,'Clean Data'!$K$2:$K$1565) | E21: =IF(B21<=$K$6,5,IF(B21<=$K$7,4,IF(B21<=$K$8,3,IF(B21<=$K$9,2,1)))) | F21: =IF(C21>=$L$9,5,IF(C21>=$L$8,4,IF(C21>=$L$7,3,IF(C21>=$L$6,2,1)))) | G21: =IF(D21>=$M$9,5,IF(D21>=$M$8,4,IF(D21>=$M$7,3,IF(D21>=$M$6,2,1)))) | H21: =IF(AND(E21>=4,F21>=4),"Champions",IF(AND(E21>=3,F21>=3),"Loyal",IF(AND(E21>=4,F21<=2),"New customers",IF(AND(E21=3,F21<=2),"Potential",IF(AND(E21<=2,F21>=3),"At risk","Inactive")))))
... A437: C1429 | B437: =$B$4-_xlfn.MAXIFS('Clean Data'!$B$2:$B$1565,'Clean Data'!$C$2:$C$1565,$A437) | C437: =COUNTIF('Clean Data'!$C$2:$C$1565,$A437) | D437: =SUMIF('Clean Data'!$C$2:$C$1565,$A437,'Clean Data'!$K$2:$K$1565) | E437: =IF(B437<=$K$6,5,IF(B437<=$K$7,4,IF(B437<=$K$8,3,IF(B437<=$K$9,2,1)))) | F437: =IF(C437>=$L$9,5,IF(C437>=$L$8,4,IF(C437>=$L$7,3,IF(C437>=$L$6,2,1)))) | G437: =IF(D437>=$M$9,5,IF(D437>=$M$8,4,IF(D437>=$M$7,3,IF(D437>=$M$6,2,1)))) | H437: =IF(AND(E437>=4,F437>=4),"Champions",IF(AND(E437>=3,F437>=3),"Loyal",IF(AND(E437>=4,F437<=2),"New customers",IF(AND(E437=3,F437<=2),"Potential",IF(AND(E437<=2,F437>=3),"At risk","Inactive")))))

Sheet Analysis
A1: ANALYSIS (every value is a live formula referencing Clean Data and RFM)
A3: Key metrics | F3: Revenue by channel
A4: Total revenue | B4: =SUM('Clean Data'!$K$2:$K$1565) | F4: Item | G4: Revenue | H4: Orders
A5: Total orders | B5: =COUNTA('Clean Data'!$A$2:$A$1565) | F5: Offline Store | G5: =SUMIFS('Clean Data'!$K$2:$K$1565,'Clean Data'!$E$2:$E$1565,$F5) | H5: =COUNTIFS('Clean Data'!$E$2:$E$1565,$F5)
A6: Average order value | B6: =B4/B5 | F6: Shopee | G6: =SUMIFS('Clean Data'!$K$2:$K$1565,'Clean Data'!$E$2:$E$1565,$F6) | H6: =COUNTIFS('Clean Data'!$E$2:$E$1565,$F6)
A7: Unique customers | B7: =COUNTA(RFM!$A$8:$A$437) | F7: TikTok Shop | G7: =SUMIFS('Clean Data'!$K$2:$K$1565,'Clean Data'!$E$2:$E$1565,$F7) | H7: =COUNTIFS('Clean Data'!$E$2:$E$1565,$F7)
A8: Champions (count) | B8: =COUNTIF(RFM!$H$8:$H$437,"Champions") | F8: Tokopedia | G8: =SUMIFS('Clean Data'!$K$2:$K$1565,'Clean Data'!$E$2:$E$1565,$F8) | H8: =COUNTIFS('Clean Data'!$E$2:$E$1565,$F8)
A9: Champions revenue share | B9: =SUMIF(RFM!$H$8:$H$437,"Champions",RFM!$D$8:$D$437)/B4
A10: At risk (count) | B10: =COUNTIF(RFM!$H$8:$H$437,"At risk") | F10: Revenue by category
F11: Item | G11: Revenue | H11: Orders
F12: Elektronik | G12: =SUMIFS('Clean Data'!$K$2:$K$1565,'Clean Data'!$G$2:$G$1565,$F12) | H12: =COUNTIFS('Clean Data'!$G$2:$G$1565,$F12)
A13: Revenue by month | F13: Fashion | G13: =SUMIFS('Clean Data'!$K$2:$K$1565,'Clean Data'!$G$2:$G$1565,$F13) | H13: =COUNTIFS('Clean Data'!$G$2:$G$1565,$F13)
A14: Month | B14: Orders | C14: Revenue | D14: AOV | F14: Kecantikan | G14: =SUMIFS('Clean Data'!$K$2:$K$1565,'Clean Data'!$G$2:$G$1565,$F14) | H14: =COUNTIFS('Clean Data'!$G$2:$G$1565,$F14)
A15: 2025-01 | B15: =COUNTIFS('Clean Data'!$L$2:$L$1565,$A15) | C15: =SUMIFS('Clean Data'!$K$2:$K$1565,'Clean Data'!$L$2:$L$1565,$A15) | D15: =IFERROR(C15/B15,0) | F15: Makanan | G15: =SUMIFS('Clean Data'!$K$2:$K$1565,'Clean Data'!$G$2:$G$1565,$F15) | H15: =COUNTIFS('Clean Data'!$G$2:$G$1565,$F15)
A16: 2025-02 | B16: =COUNTIFS('Clean Data'!$L$2:$L$1565,$A16) | C16: =SUMIFS('Clean Data'!$K$2:$K$1565,'Clean Data'!$L$2:$L$1565,$A16) | D16: =IFERROR(C16/B16,0) | F16: Rumah Tangga | G16: =SUMIFS('Clean Data'!$K$2:$K$1565,'Clean Data'!$G$2:$G$1565,$F16) | H16: =COUNTIFS('Clean Data'!$G$2:$G$1565,$F16)
A17: 2025-03 | B17: =COUNTIFS('Clean Data'!$L$2:$L$1565,$A17) | C17: =SUMIFS('Clean Data'!$K$2:$K$1565,'Clean Data'!$L$2:$L$1565,$A17) | D17: =IFERROR(C17/B17,0)
A18: 2025-04 | B18: =COUNTIFS('Clean Data'!$L$2:$L$1565,$A18) | C18: =SUMIFS('Clean Data'!$K$2:$K$1565,'Clean Data'!$L$2:$L$1565,$A18) | D18: =IFERROR(C18/B18,0) | F18: Revenue by RFM segment
A19: 2025-05 | B19: =COUNTIFS('Clean Data'!$L$2:$L$1565,$A19) | C19: =SUMIFS('Clean Data'!$K$2:$K$1565,'Clean Data'!$L$2:$L$1565,$A19) | D19: =IFERROR(C19/B19,0) | F19: Segment | G19: Revenue | H19: Customers
A20: 2025-06 | B20: =COUNTIFS('Clean Data'!$L$2:$L$1565,$A20) | C20: =SUMIFS('Clean Data'!$K$2:$K$1565,'Clean Data'!$L$2:$L$1565,$A20) | D20: =IFERROR(C20/B20,0) | F20: Champions | G20: =SUMIF(RFM!$H$8:$H$437,$F20,RFM!$D$8:$D$437) | H20: =COUNTIF(RFM!$H$8:$H$437,$F20)
A21: 2025-07 | B21: =COUNTIFS('Clean Data'!$L$2:$L$1565,$A21) | C21: =SUMIFS('Clean Data'!$K$2:$K$1565,'Clean Data'!$L$2:$L$1565,$A21) | D21: =IFERROR(C21/B21,0) | F21: Loyal | G21: =SUMIF(RFM!$H$8:$H$437,$F21,RFM!$D$8:$D$437) | H21: =COUNTIF(RFM!$H$8:$H$437,$F21)
A22: 2025-08 | B22: =COUNTIFS('Clean Data'!$L$2:$L$1565,$A22) | C22: =SUMIFS('Clean Data'!$K$2:$K$1565,'Clean Data'!$L$2:$L$1565,$A22) | D22: =IFERROR(C22/B22,0) | F22: New customers | G22: =SUMIF(RFM!$H$8:$H$437,$F22,RFM!$D$8:$D$437) | H22: =COUNTIF(RFM!$H$8:$H$437,$F22)
A23: 2025-09 | B23: =COUNTIFS('Clean Data'!$L$2:$L$1565,$A23) | C23: =SUMIFS('Clean Data'!$K$2:$K$1565,'Clean Data'!$L$2:$L$1565,$A23) | D23: =IFERROR(C23/B23,0) | F23: Potential | G23: =SUMIF(RFM!$H$8:$H$437,$F23,RFM!$D$8:$D$437) | H23: =COUNTIF(RFM!$H$8:$H$437,$F23)
A24: 2025-10 | B24: =COUNTIFS('Clean Data'!$L$2:$L$1565,$A24) | C24: =SUMIFS('Clean Data'!$K$2:$K$1565,'Clean Data'!$L$2:$L$1565,$A24) | D24: =IFERROR(C24/B24,0) | F24: At risk | G24: =SUMIF(RFM!$H$8:$H$437,$F24,RFM!$D$8:$D$437) | H24: =COUNTIF(RFM!$H$8:$H$437,$F24)
A25: 2025-11 | B25: =COUNTIFS('Clean Data'!$L$2:$L$1565,$A25) | C25: =SUMIFS('Clean Data'!$K$2:$K$1565,'Clean Data'!$L$2:$L$1565,$A25) | D25: =IFERROR(C25/B25,0) | F25: Inactive | G25: =SUMIF(RFM!$H$8:$H$437,$F25,RFM!$D$8:$D$437) | H25: =COUNTIF(RFM!$H$8:$H$437,$F25)
A26: 2025-12 | B26: =COUNTIFS('Clean Data'!$L$2:$L$1565,$A26) | C26: =SUMIFS('Clean Data'!$K$2:$K$1565,'Clean Data'!$L$2:$L$1565,$A26) | D26: =IFERROR(C26/B26,0)
A27: 2026-01 | B27: =COUNTIFS('Clean Data'!$L$2:$L$1565,$A27) | C27: =SUMIFS('Clean Data'!$K$2:$K$1565,'Clean Data'!$L$2:$L$1565,$A27) | D27: =IFERROR(C27/B27,0)
A28: 2026-02 | B28: =COUNTIFS('Clean Data'!$L$2:$L$1565,$A28) | C28: =SUMIFS('Clean Data'!$K$2:$K$1565,'Clean Data'!$L$2:$L$1565,$A28) | D28: =IFERROR(C28/B28,0)
A29: 2026-03 | B29: =COUNTIFS('Clean Data'!$L$2:$L$1565,$A29) | C29: =SUMIFS('Clean Data'!$K$2:$K$1565,'Clean Data'!$L$2:$L$1565,$A29) | D29: =IFERROR(C29/B29,0)
A30: 2026-04 | B30: =COUNTIFS('Clean Data'!$L$2:$L$1565,$A30) | C30: =SUMIFS('Clean Data'!$K$2:$K$1565,'Clean Data'!$L$2:$L$1565,$A30) | D30: =IFERROR(C30/B30,0)
A31: 2026-05 | B31: =COUNTIFS('Clean Data'!$L$2:$L$1565,$A31) | C31: =SUMIFS('Clean Data'!$K$2:$K$1565,'Clean Data'!$L$2:$L$1565,$A31) | D31: =IFERROR(C31/B31,0)
A32: 2026-06 | B32: =COUNTIFS('Clean Data'!$L$2:$L$1565,$A32) | C32: =SUMIFS('Clean Data'!$K$2:$K$1565,'Clean Data'!$L$2:$L$1565,$A32) | D32: =IFERROR(C32/B32,0)
A35: Pareto: products by revenue (cumulative share)
A36: Product | B36: Revenue | C36: Cumulative %
A37: Set Wadah Kedap | B37: =SUMIF('Clean Data'!$H$2:$H$1565,$A37,'Clean Data'!$K$2:$K$1565) | C37: =SUM($B$37:$B37)/SUM($B$37:$B$60)
A38: Webcam HD | B38: =SUMIF('Clean Data'!$H$2:$H$1565,$A38,'Clean Data'!$K$2:$K$1565) | C38: =SUM($B$37:$B38)/SUM($B$37:$B$60)
A39: Smartwatch | B39: =SUMIF('Clean Data'!$H$2:$H$1565,$A39,'Clean Data'!$K$2:$K$1565) | C39: =SUM($B$37:$B39)/SUM($B$37:$B$60)
A40: Power Bank 20K | B40: =SUMIF('Clean Data'!$H$2:$H$1565,$A40,'Clean Data'!$K$2:$K$1565) | C40: =SUM($B$37:$B40)/SUM($B$37:$B$60)
A41: Earbuds TWS | B41: =SUMIF('Clean Data'!$H$2:$H$1565,$A41,'Clean Data'!$K$2:$K$1565) | C41: =SUM($B$37:$B41)/SUM($B$37:$B$60)
A42: Celana Chino | B42: =SUMIF('Clean Data'!$H$2:$H$1565,$A42,'Clean Data'!$K$2:$K$1565) | C42: =SUM($B$37:$B42)/SUM($B$37:$B$60)
A43: Keyboard Mekanik | B43: =SUMIF('Clean Data'!$H$2:$H$1565,$A43,'Clean Data'!$K$2:$K$1565) | C43: =SUM($B$37:$B43)/SUM($B$37:$B$60)
...

Sheet Dashboard
A1: DASHBOARD
A2: E-commerce Sales and Customer Analysis. Charts read live from the Analysis tab. Same view as the web case study.
A4: Total revenue | C4: Orders | E4: Avg order value | G4: Customers | I4: Champions share | K4: At risk
A5: =Analysis!B4 | C5: =Analysis!B5 | E5: =Analysis!B6 | G5: =Analysis!B7 | I5: =Analysis!B9 | K5: =Analysis!B10
A24: Seasonal peaks around Lebaran and year-end. Plan stock and ads ahead of them.
A43: Shopee leads. Concentrate spend where revenue already converts. | I43: A few categories carry the revenue. The rest is a long tail.
A62: Champions and Loyal carry the business. At risk is revenue worth winning back now.
A82: A small set of products drives roughly 80 percent of revenue. Protect and promote those first.
A86: Recommendations
A87: - Concentrate ad spend on the top channel and the Pareto core products.
A88: - Launch a win-back offer for the At risk segment before they churn.
A89: - Reward Champions and Loyal customers, they generate most of the revenue.
A90: - Pre-stock for the seasonal peaks visible in the monthly trend.

Sheet VBA
A1: VBA AUTOMATION (also provided as Module1.bas next to this file)
A2: Paste into the VBA editor (Alt+F11, Insert, Module) to one-click clean a fresh raw paste.
A4: Attribute VB_Name = "Module1"
A5: ' One-click cleaner for a freshly pasted raw export on the "Raw Data" sheet.
A6: ' Normalises channel/category text and converts "Rp 1.234" text to real numbers.
A7: Sub CleanRawData()
A8: Dim ws As Worksheet, lastRow As Long, r As Long, v As String
A9: Set ws = ThisWorkbook.Sheets("Raw Data")
A10: lastRow = ws.Cells(ws.Rows.Count, 1).End(xlUp).Row
A11: Application.ScreenUpdating = False
A12: For r = 5 To lastRow
A13: ws.Cells(r, 5).Value = Application.WorksheetFunction.Proper(Trim(ws.Cells(r, 5).Value))
... A23: End Sub
